Workbook

Sheet Unidades Vendidas (SEMESTRE)
A1: PRODUCTO | B1: UNIDADES | C1: PESO UNITARIO (GRAMOS) | D1: GRAMOS | E1: KILOS | F1: TONELADAS
A2: SOBRETAPA SAVILOE 33M | B2: 752372 | C2: 5.7 | D2: =+B2*C2 -> 4288520.4 | E2: =+D2/1000 -> 4288.5204 | F2: =+E2/1000 -> 4.2885204 | G2: =+INT((B2/(6)/(31))) -> 4045
A3: MAQUILA ENV 1700 TRANSP CAPRI GEN.NUEVO 41 GR SM | B3: 622168 | C3: 43 | D3: =+B3*C3 -> 26753224 | E3: =+D3/1000 -> 26753.224 | F3: =+E3/1000 -> 26.753224 | G3: =+INT((B3/(6)/(31))) -> 3344
A4: MAQUILA ENV 400 CRISTAL 19 GR S.M. PET CAPRI | B4: 430329 | C4: 19 | D4: =+B4*C4 -> 8176251 | E4: =+D4/1000 -> 8176.251 | F4: =+E4/1000 -> 8.176251 | G4: =+INT((B4/(6)/(31))) -> 2313
A5: SOBRETAPA VV VERDE SF QUALA | B5: 379322 | C5: 6.2 | D5: =+B5*C5 -> 2351796.4 | E5: =+D5/1000 -> 2351.7964 | F5: =+E5/1000 -> 2.3517964 | G5: =+INT((B5/(6)/(31))) -> 2039
A6: MAQUILA ENV 400 CRISTAL 17 GR S.M. PET CAPRI | B6: 333531 | C6: 19 | D6: =+B6*C6 -> 6337089 | E6: =+D6/1000 -> 6337.089 | F6: =+E6/1000 -> 6.337089 | G6: =+INT((B6/(6)/(31))) -> 1793
A7: MAQUILA ENV 1000 PET CAPRI NUEVO 31 GR TRANSP SM | B7: 200801 | C7: 34 | D7: =+B7*C7 -> 6827234 | E7: =+D7/1000 -> 6827.234 | F7: =+E7/1000 -> 6.827234 | G7: =+INT((B7/(6)/(31))) -> 1079
A8: MAQULA ENVE 335 CM3 PET PETALOIDE TRANS 18 GR | B8: 197880 | C8: 19 | D8: =+B8*C8 -> 3759720 | E8: =+D8/1000 -> 3759.72 | F8: =+E8/1000 -> 3.75972 | G8: =+INT((B8/(6)/(31))) -> 1063
A9: TAPA 28 MM CONICA AMARILLA | B9: 190465 | C9: 5.7 | D9: =+B9*C9 -> 1085650.5 | E9: =+D9/1000 -> 1085.6505 | F9: =+E9/1000 -> 1.0856505 | G9: =+INT((B9/(6)/(31))) -> 1024
A10: MAQUILA BOTELLA W240 QUALA | B10: 173712 | C10: 12.67 | D10: =+B10*C10 -> 2200931 | E10: =+D10/1000 -> 2200.931 | F10: =+E10/1000 -> 2.200931 | G10: =+INT((B10/(6)/(31))) -> 933
A11: PREFORMA SN 20 GRS CRISTAL | B11: 162286 | C11: 21 | D11: =+B11*C11 -> 3408006 | E11: =+D11/1000 -> 3408.006 | F11: =+E11/1000 -> 3.408006 | G11: =+INT((B11/(6)/(31))) -> 872
A12: TAPA PP ARO DEEP BLUE 90 ML | B12: 129815 | C12: 13.5 | D12: =+B12*C12 -> 1752502.5 | E12: =+D12/1000 -> 1752.5025 | F12: =+E12/1000 -> 1.7525025 | G12: =+INT((B12/(6)/(31))) -> 697
A13: ENVASE 600 BALA ML PET 20 GR | B13: 128582 | C13: 21 | D13: =+B13*C13 -> 2700222 | E13: =+D13/1000 -> 2700.222 | F13: =+E13/1000 -> 2.700222 | G13: =+INT((B13/(6)/(31))) -> 691
... A102: 20622089 TAPA INSTACREAM 175 GR QUALA | B102: 9215 | C102: 28 | D102: =+B102*C102 -> 258020 | E102: =+D102/1000 -> 258.02 | F102: =+E102/1000 -> 0.25802 | G102: =+INT((B102/(6)/(31))) -> 49
A103: MAQUILA ENVASE 2000 PET BLANCO FULLER | B103: 9165 | C103: 29 | D103: =+B103*C103 -> 265785 | E103: =+D103/1000 -> 265.785 | F103: =+E103/1000 -> 0.265785
A104: ENVASE GALON PET TRANS REDONDO T38 | B104: 8937 | C104: 23 | D104: =+B104*C104 -> 205551 | E104: =+D104/1000 -> 205.551 | F104: =+E104/1000 -> 0.205551
A105: ENVASE 2000 CM3 PET ACEITE SF GENERICO | B105: 8649 | C105: 6 | D105: =+B105*C105 -> 51894 | E105: =+D105/1000 -> 51.894 | F105: =+E105/1000 -> 0.051894
A106: ENVASE 500 ANATOMICO PET | B106: 8608 | C106: 28 | D106: =+B106*C106 -> 241024 | E106: =+D106/1000 -> 241.024 | F106: =+E106/1000 -> 0.241024
A107: TAPA MAXTER 38MM VINOTINTO ARINTIA | B107: 8572 | C107: 22 | D107: =+B107*C107 -> 188584 | E107: =+D107/1000 -> 188.584 | F107: =+E107/1000 -> 0.188584
A108: ENVASE BEG 1/4 T 38 AZUL | B108: 8536 | C108: 17 | D108: =+B108*C108 -> 145112 | E108: =+D108/1000 -> 145.112 | F108: =+E108/1000 -> 0.145112
A109: ENVASE 250 OLEOLLANO AKK PET | B109: 8383 | C109: 8 | D109: =+B109*C109 -> 67064 | E109: =+D109/1000 -> 67.064 | F109: =+E109/1000 -> 0.067064
A110: ENVASE LEDESA 2000 CM3 PRIMA PE BLANCO | B110: 8336 | C110: 20 | D110: =+B110*C110 -> 166720 | E110: =+D110/1000 -> 166.72 | F110: =+E110/1000 -> 0.16672
A111: MOLDE ENVASE 300ML GRECIA AMBAR PET BISONTE | B111: 8100 | C111: 9 | D111: =+B111*C111 -> 72900 | E111: =+D111/1000 -> 72.9 | F111: =+E111/1000 -> 0.0729
A112: 64349297TAPA PP ROSCA FAB TRANS 90ML MINISOU | B112: 7840 | C112: 27 | D112: =+B112*C112 -> 211680 | E112: =+D112/1000 -> 211.68 | F112: =+E112/1000 -> 0.21168
A113: TAPA 38 MM VERDE NUEVA | B113: 7783 | C113: 5 | D113: =+B113*C113 -> 38915 | E113: =+D113/1000 -> 38.915 | F113: =+E113/1000 -> 0.038915
A114: ENV 3000 ACEITE T28 SF PET | B114: 7458 | C114: 28 | D114: =+B114*C114 -> 208824 | E114: =+D114/1000 -> 208.824 | F114: =+E114/1000 -> 0.208824
... A200: ENVASE 4 LITROS REDONDO BOCA 38 | B200: 2596 | C200: 31 | D200: =+B200*C200 -> 80476 | E200: =+D200/1000 -> 80.476 | F200: =+E200/1000 -> 0.080476
A201: TAPA DETERGENTE AZUL PP | B201: 2581

Sheet Data de Máquinas
A1: Máquina | B1: Indicador | C1: SetUp Promedio
A2: MAQUINA EXTRUSION SOPLADO AUTOBLOW 570 #1 | B2: M1 | C2: 98.666
A3: MAQUINA EXTRUSION SOPLADO AUTOBLOW 400D #2 | B3: M2 | C3: 94
A4: MAQUINA EXTRUSION SOPLADO B 30 | B4: M3 | C4: 55.58
A5: MAQUINA EXTRUSION SOPLADO BATTENFELD VK3-1 | B5: M4 | C5: 60
A6: MAQUINA EXTRUSION SOPLADO BEKUM BAE 1-1 | B6: M5 | C6: 19.45
A7: MAQUINA EXTRUSION SOPLADO KAUTEX #1 | B7: M6 | C7: 72.5
A8: MAQUINA EXTRUSION SOPLADO UNILOY A-1 | B8: M7 | C8: 14.65
A9: MAQUINA EXTRUSION SOPLADO UNILOY A-2 | B9: M8 | C9: 14.65
A10: MAQUINA EXTRUSION SOPLADO BEKUM BM08-4 | B10: M9 | C10: 33
A11: MAQUINA EXTRUSION SOPLADO ECOBLOW 600D/100 #2 | B11: M10 | C11: 85
C12: =AVERAGE(C2:C11) -> 54.7496 | D12: Promedio General
C13: En minutos
A27: Máquina | B27: Indicador | C27: SetUp Promedio
A28: MAQUINA EXTRUSION SOPLADO AUTOBLOW 570 #1 | B28: M1 | C28: 98.666
A29: MAQUINA EXTRUSION SOPLADO AUTOBLOW 400D #2 | B29: M2 | C29: 94
A30: MAQUINA EXTRUSION SOPLADO B 30 | B30: M3 | C30: 55.58
A31: MAQUINA EXTRUSION SOPLADO BATTENFELD VK3-1 | B31: M4 | C31: 60
A32: MAQUINA EXTRUSION SOPLADO BEKUM BAE 1-1 | B32: M5 | C32: 19.45
A33: MAQUINA EXTRUSION SOPLADO KAUTEX #1 | B33: M6 | C33: 72.5
A34: MAQUINA EXTRUSION SOPLADO UNILOY A-1 | B34: M7 | C34: 14.65
A35: MAQUINA EXTRUSION SOPLADO UNILOY A-2 | B35: M8 | C35: 14.65
A36: MAQUINA EXTRUSION SOPLADO BEKUM BM08-4 | B36: M9 | C36: 33
A37: MAQUINA EXTRUSION SOPLADO ECOBLOW 600D/100 #2 | B37: M10 | C37: 85
C38: =AVERAGE(C28:C37) -> 54.7496 | D38: Promedio General
C39: En minutos

Sheet MODELO PL
A1: TIEMPO PROMEDIO REGISTRADO POR CADA MÁQUINA EN PRODUCIR CADA REFERENCIA (EN MINUTOS)
A2: PRODUCTO | B2: M1 | C2: M2 | D2: M3 | E2: M4 | F2: M5 | G2: M6 | H2: M7 | I2: M8 | J2: M9 | K2: M10
A3: SOBRETAPA SAVILOE 33M | B3: 0.85 | C3: 0.65388889 | D3: 1.1594444 | E3: 1.0338889 | F3: 0.735 | G3: 0.74055556 | H3: 0.61944444 | I3: 0.735 | J3: 0.85055556 | K3: 0.90833333
A4: MAQUILA ENV 1700 TRANSP CAPRI GEN.NUEVO 41 GR SM | B4: 0.85021164 | C4: 0.85021164 | D4: 0.65277778 | E4: 0.64333333 | F4: 1.0053704 | G4: 0.85021164 | H4: 0.72388889 | I4: 0.98555556 | J4: 1.3066667 | K4: 0.63388889
A5: MAQUILA ENV 400 CRISTAL 19 GR S.M. PET CAPRI | B5: 0.47888889 | C5: 0.86 | D5: 0.80611111 | E5: 0.85083333 | F5: 1.1172222 | G5: 0.81722222 | H5: 0.69833333 | I5: 1.5361111 | J5: 1.1172222 | K5: 0.89555556
A6: SOBRETAPA VV VERDE SF QUALA | B6: 0.39222222 | C6: 0.86 | D6: 0.95166667 | E6: 0.83305556 | F6: 1.0075926 | G6: 0.96666667 | H6: 1.6683333 | I6: 0.81111111 | J6: 0.54333333 | K6: 0.71444444
A7: MAQUILA ENV 400 CRISTAL 17 GR S.M. PET CAPRI | B7: 0.84611111 | C7: 0.92944444 | D7: 0.89888889 | E7: 0.83694444 | F7: 1.1474074 | G7: 0.76277778 | H7: 1.3827778 | I7: 0.64055556 | J7: 1.4188889 | K7: 0.775
A8: MAQUILA ENV 1000 PET CAPRI NUEVO 31 GR TRANSP SM | B8: 0.62777778 | C8: 0.62777778 | D8: 1.1611111 | E8: 1.0480556 | F8: 0.7312963 | G8: 0.62777778 | H8: 0.74333333 | I8: 0.65777778 | J8: 0.79277778 | K8: 0.935
A9: MAQULA ENVE 335 CM3 PET PETALOIDE TRANS 18 GR | B9: 0.74888889 | C9: 0.59111111 | D9: 0.73777778 | E9: 0.73444444 | F9: 0.88092593 | G9: 0.90666667 | H9: 0.93111111 | I9: 1.0816667 | J9: 0.63 | K9: 0.73111111
A10: TAPA 28 MM CONICA AMARILLA | B10: 0.47666667 | C10: 1.1872222 | D10: 0.78833333 | E10: 0.88777778 | F10: 0.80462963 | G10: 1.1305556 | H10: 0.79722222 | I10: 0.96222222 | J10: 0.65444444 | K10: 0.98722222
A11: MAQUILA BOTELLA W240 QUALA | B11: 0.55166667 | C11: 0.87944444 | D11: 0.66833333 | E11: 0.72055556 | F11: 0.81574074 | G11: 1.0983333 | H11: 0.62 | I11: 1.0188889 | J11: 0.80833333 | K11: 0.77277778
A12: PREFORMA SN 20 GRS CRISTAL | B12: 0.97833333 | C12: 0.70888889 | D12: 0.85722222 | E12: 0.88305556 | F12: 0.91361111 | G12: 1.2477778 | H12: 1.2811111 | I12: 0.91361111 | J12: 0.54611111 | K12: 0.90888889
A13: TAPA PP ARO DEEP BLUE 90 ML | B13: 0.9 | C13: 0.9 | D13: 1.0027778 | E13: 0.85611111 | F13: 0.64388889 | G13: 0.9 | H13: 0.55222222 | I13: 0.88555556 | J13: 0.49388889 | K13: 0.70944444
A14: ENVASE 600 BALA ML PET 20 GR | B14: 1.2183333 | C14: 0.97444444 | D14: 0.89222222 | E14: 0.84777778 | F14: 0.94685185 | G14: 1.4622222 | H14: 1.0255556 | I14: 0.74666667 | J14: 1.0683333 | K14: 0.80333333
... A103: Set-up Time (en minutos) | B103: 98.666 | C103: 94 | D103: 55.58 | E103: 60 | F103: 19.45 | G103: 72.5 | H103: 14.65 | I103: 14.65 | J103: 33 | K103: 85
A105: F.O: Minimizar Z= | B105: =(SUMPRODUCT($B$109:$K$207,$B$3:$K$101))+(SUMPRODUCT($B$103:$K$103,$B$209:$K$209)) -> 13694.062 | C105: minutos
A108: PRODUCTO | B108: M1 | C108: M2 | D108: M3 | E108: M4 | F108: M5 | G108: M6 | H108: M7 | I108: M8 | J108: M9 | K108: M10 | L108: SUMA | N108: DEMANDA
A109: SOBRETAPA SAVILOE 33M | H109: 1618 | L109: =SUM(B109:K109) -> 1618 | M109: >= | N109: 1618 | O109: =+N109-L109 -> 0
A110: MAQUILA ENV 1700 TRANSP CAPRI GEN.NUEVO 41 GR SM | K110: 1337 | L110: =SUM(B110:K110) -> 1337 | M110: >= | N110: 1337 | O110: =+N110-L110 -> 0
A111: MAQUILA ENV 400 CRISTAL 19 GR S.M. PET CAPRI | B111: 1244 | L111: =SUM(B111:K111) -> 1244 | M111: >= | N111: 1244 | O111: =+N111-L111 -> 0
A112: SOBRETAPA VV VERDE SF QUALA | B112: 815 | D112: 350 | L112: =SUM(B112:K112) -> 1165 | M112: >= | N112: 1165 | O112: =+N112-L112 -> 0
A113: MAQUILA ENV 400 CRISTAL 17 GR S.M. PET CAPRI | I113: 1044 | L113: =SUM(B113:K113) -> 1044 | M113: >= | N113: 1044 | O113: =+N113-L113 -> 0
A114: MAQUILA ENV 1000 PET CAPRI NUEVO 31 GR TRANSP SM | E114: 344 | F114: 303 | L114: =SUM(B114:K114) -> 647 | M114: >= | N114: 647 | O114: =+N114-L114 -> 0
A115: MAQULA ENVE 335 CM3 PET PETALOIDE TRANS 18 GR | C115: 335 | F115: 90 | L115: =SUM(B115:K115) -> 425 | M115: >= | N115: 425 | O115: =+N115-L115 -> 0
A116: TAPA 28 MM CONICA AMARILLA | B116: 300 | G116: 109 | L116: =SUM(B116:K116) -> 409 | M116: >= | N116: 409 | O116: =+N116-L116 -> 0
A117: MAQUILA BOTELLA W240 QUALA | F117: 205 | H117: 168 | L117: =SUM(B117:K117) -> 373 | M117: >= | N117: 373 | O117: =+N117-L117 -> 0
A118: PREFORMA SN 20 GRS CRISTAL | J118: 348 | L118: =SUM(B118:K118) -> 348 | M118: >= | N118: 348 | O118: =+N118-L118 -> 0
A119: TAPA PP ARO DEEP BLUE 90 ML | J119: 278 | L119: =SUM(B119:K119) -> 278 | M119: >= | N119: 278 | O119: =+N119-L119 -> 0
A120: ENVASE 600 BALA ML PET 20 GR | I120: 276 | L120: =SUM(B120:K120) -> 276 | M120: >= | N120: 276 | O120: =+N120-L120 -> 0
A121: ENVASE 810 PET BISONTE | F121: 275 | L121: =SUM(B121:K121) -> 275 | M121: >= | N121: 275 | O121: =+N121-L121 -> 0
A122: MAQUILA ENV 500 ANATOMICO LPS PET | G122: 265 | L122: =SUM(B122:K122) -> 265 | M122: >= | N122: 265 | O122: =+N122-L122 -> 0
A123: TAPA SUAVIZANTE FUCSIA | D123: 260 | L123: =SUM(B123:K123) -> 260 | M123: >= | N123: 260 | O123: =+N123-L123 -> 0
A124: TAPA SAV ACO COLAGENO 530 ML PE | I124: 175 | L124: =SUM(B124:K124) -> 175 | M124: >= | N124: 175 | O124: =+N124-L124 -> 0
A125: MAQUILA ENV PET 400 MAXI CAPRI 18 GR SM | C125: 162 | L125: =SUM(B125:K125) -> 162 | M125: >= | N125: 162 | O125: =+N125-L125 -> 0
A126: TAPA GRIS ROS EGO CERA 160 ML | H126: 150 | L126: =SUM(B126:K126) -> 150 | M126: >= | N126: 150 | O126: =+N126-L126 -> 0
A127: ENVASE BRILLA KING 500 BLANCO | I127: 138 | L127: =SUM(B127:K127) -> 138 | M127: >= | N127: 138 | O127: =+N127-L127 -> 0
A128: ENVASE 4 LTS SUAVIZANTE AMARILLO PEADS | C128: 128 | L128: =SUM(B128:K128) -> 128 | M128: >= | N128: 128 | O128: =+N128-L128 -> 0
A129: TAPA FLIT TOP JABON INTIMO KOBA | D129: 101 | L129: =SUM(B129:K129) -> 101 | M129: >= | N129: 101 | O129: =+N129-L129 -> 0
A130: 32160012SOBRETAPA VV AZUL SF | E130: 97 | L130: =SUM(B130:K130) -> 97 | M130: >= | N130: 97 | O130: =+N130-L130 -> 0
A131: 67525342 TAPA CUADRADA EGO GEL NEGRA 240 | E131: 86 | L131: =SUM(B131:K131) -> 86 | M131: >= | N131: 86 | O131: =+N131-L131 -> 0
...

Sheet DATOS SIMULADOS
A1: TIEMPO PROMEDIO REGISTRADO POR CADA MÁQUINA EN PRODUCIR CADA REFERENCIA (EN SEGUNDOS)
A2: PRODUCTO | B2: M1 | C2: M2 | D2: M3 | E2: M4 | F2: M5 | G2: M6 | H2: M7 | I2: M8 | J2: M9 | K2: M10
A3: SOBRETAPA SAVILOE 33M | B3: 51 | C3: 39.233333 | D3: 69.566667 | E3: 62.033333 | F3: 44.1 | G3: 44.433333 | H3: 37.166667 | I3: 44.1 | J3: 51.033333 | K3: 54.5
A4: MAQUILA ENV 1700 TRANSP CAPRI GEN.NUEVO 41 GR SM | B4: 51.012698 | C4: 51.012698 | D4: 39.166667 | E4: 38.6 | F4: 60.322222 | G4: 51.012698 | H4: 43.433333 | I4: 59.133333 | J4: 78.4 | K4: 38.033333
A5: MAQUILA ENV 400 CRISTAL 19 GR S.M. PET CAPRI | B5: 28.733333 | C5: 51.6 | D5: 48.366667 | E5: 51.05 | F5: 67.033333 | G5: 49.033333 | H5: 41.9 | I5: 92.166667 | J5: 67.033333 | K5: 53.733333
A6: SOBRETAPA VV VERDE SF QUALA | B6: 23.533333 | C6: 51.6 | D6: 57.1 | E6: 49.983333 | F6: 60.455556 | G6: 58 | H6: 100.1 | I6: 48.666667 | J6: 32.6 | K6: 42.866667
A7: MAQUILA ENV 400 CRISTAL 17 GR S.M. PET CAPRI | B7: 50.766667 | C7: 55.766667 | D7: 53.933333 | E7: 50.216667 | F7: 68.844444 | G7: 45.766667 | H7: 82.966667 | I7: 38.433333 | J7: 85.133333 | K7: 46.5
A8: MAQUILA ENV 1000 PET CAPRI NUEVO 31 GR TRANSP SM | B8: 37.666667 | C8: 37.666667 | D8: 69.666667 | E8: 62.883333 | F8: 43.877778 | G8: 37.666667 | H8: 44.6 | I8: 39.466667 | J8: 47.566667 | K8: 56.1
A9: MAQULA ENVE 335 CM3 PET PETALOIDE TRANS 18 GR | B9: 44.933333 | C9: 35.466667 | D9: 44.266667 | E9: 44.066667 | F9: 52.855556 | G9: 54.4 | H9: 55.866667 | I9: 64.9 | J9: 37.8 | K9: 43.866667
A10: TAPA 28 MM CONICA AMARILLA | B10: 28.6 | C10: 71.233333 | D10: 47.3 | E10: 53.266667 | F10: 48.277778 | G10: 67.833333 | H10: 47.833333 | I10: 57.733333 | J10: 39.266667 | K10: 59.233333
A11: MAQUILA BOTELLA W240 QUALA | B11: 33.1 | C11: 52.766667 | D11: 40.1 | E11: 43.233333 | F11: 48.944444 | G11: 65.9 | H11: 37.2 | I11: 61.133333 | J11: 48.5 | K11: 46.366667
A12: PREFORMA SN 20 GRS CRISTAL | B12: 58.7 | C12: 42.533333 | D12: 51.433333 | E12: 52.983333 | F12: 54.816667 | G12: 74.866667 | H12: 76.866667 | I12: 54.816667 | J12: 32.766667 | K12: 54.533333
A13: TAPA PP ARO DEEP BLUE 90 ML | B13: 54 | C13: 54 | D13: 60.166667 | E13: 51.366667 | F13: 38.633333 | G13: 54 | H13: 33.133333 | I13: 53.133333 | J13: 29.633333 | K13: 42.566667
A14: ENVASE 600 BALA ML PET 20 GR | B14: 73.1 | C14: 58.466667 | D14: 53.533333 | E14: 50.866667 | F14: 56.811111 | G14: 87.733333 | H14: 61.533333 | I14: 44.8 | J14: 64.1 | K14: 48.2
... A202: TAPA DETERGENTE AZUL PP | B202: 45.958333 | C202: 43.1125 | D202: 63.566667 | E202: 58.966667 | F202: 38.466667 | G202: 40.266667 | H202: 50.566667 | I202: 68.933333 | J202: 44.3 | K202: 54.366667

Sheet DATOS FINALES
A1: TIEMPO PROMEDIO REGISTRADO POR CADA MÁQUINA EN PRODUCIR CADA REFERENCIA (EN SEGUNDOS)
A2: PRODUCTO | B2: M1 | C2: M2 | D2: M3 | E2: M4 | F2: M5 | G2: M6 | H2: M7 | I2: M8 | J2: M9 | K2: M10
A3: SOBRETAPA SAVILOE 33M | B3: =+'Datos M1'!AF3 -> 51 | C3: =+'Datos M2'!AF3 -> 39.233333 | D3: =+'Datos M3'!AF3 -> 69.566667 | E3: =+'Datos M4'!AF3 -> 0 | F3: =+'Datos M5'!AF3 -> 0 | G3: =+'Datos M6'!AF3 -> 44.433333 | H3: =+'Datos M7'!AF3 -> 37.166667 | I3: =+'Datos M8'!AF3 -> 0 | J3: =+'Datos M9'!AF3 -> 51.033333 | K3: =+'Datos M10'!AF3 -> 54.5
A4: MAQUILA ENV 1700 TRANSP CAPRI GEN.NUEVO 41 GR SM | B4: =+'Datos M1'!AF4 -> 0 | C4: =+'Datos M2'!AF4 -> 0 | D4: =+'Datos M3'!AF4 -> 39.166667 | E4: =+'Datos M4'!AF4 -> 0 | F4: =+'Datos M5'!AF4 -> 0 | G4: =+'Datos M6'!AF4 -> 0 | H4: =+'Datos M7'!AF4 -> 43.433333 | I4: =+'Datos M8'!AF4 -> 59.133333 | J4: =+'Datos M9'!AF4 -> 78.4 | K4: =+'Datos M10'!AF4 -> 38.033333
A5: MAQUILA ENV 400 CRISTAL 19 GR S.M. PET CAPRI | B5: =+'Datos M1'!AF5 -> 28.733333 | C5: =+'Datos M2'!AF5 -> 51.6 | D5: =+'Datos M3'!AF5 -> 48.366667 | E5: =+'Datos M4'!AF5 -> 0 | F5: =+'Datos M5'!AF5 -> 0 | G5: =+'Datos M6'!AF5 -> 49.033333 | H5: =+'Datos M7'!AF5 -> 41.9 | I5: =+'Datos M8'!AF5 -> 92.166667 | J5: =+'Datos M9'!AF5 -> 0 | K5: =+'Datos M10'!AF5 -> 53.733333
A6: SOBRETAPA VV VERDE SF QUALA | B6: =+'Datos M1'!AF6 -> 23.533333 | C6: =+'Datos M2'!AF6 -> 51.6 | D6: =+'Datos M3'!AF6 -> 57.1 | E6: =+'Datos M4'!AF6 -> 0 | F6: =+'Datos M5'!AF6 -> 0 | G6: =+'Datos M6'!AF6 -> 58 | H6: =+'Datos M7'!AF6 -> 100.1 | I6: =+'Datos M8'!AF6 -> 48.666667 | J6: =+'Datos M9'!AF6 -> 32.6 | K6: =+'Datos M10'!AF6 -> 42.866667
A7: MAQUILA ENV 400 CRISTAL 17 GR S.M. PET CAPRI | B7: =+'Datos M1'!AF7 -> 0 | C7: =+'Datos M2'!AF7 -> 55.766667 | D7: =+'Datos M3'!AF7 -> 53.933333 | E7: =+'Datos M4'!AF7 -> 0 | F7: =+'Datos M5'!AF7 -> 33.733333 | G7: =+'Datos M6'!AF7 -> 45.766667 | H7: =+'Datos M7'!AF7 -> 82.966667 | I7: =+'Datos M8'!AF7 -> 38.433333 | J7: =+'Datos M9'!AF7 -> 85.133333 | K7: =+'Datos M10'!AF7 -> 46.5
A8: MAQUILA ENV 1000 PET CAPRI NUEVO 31 GR TRANSP SM | B8: =+'Datos M1'!AF8 -> 0 | C8: =+'Datos M2'!AF8 -> 0 | D8: =+'Datos M3'!AF8 -> 69.666667 | E8: =+'Datos M4'!AF8 -> 0 | F8: =+'Datos M5'!AF8 -> 0 | G8: =+'Datos M6'!AF8 -> 37.666667 | H8: =+'Datos M7'!AF8 -> 44.6 | I8: =+'Datos M8'!AF8 -> 39.466667 | J8: =+'Datos M9'!AF8 -> 47.566667 | K8: =+'Datos M10'!AF8 -> 56.1
A9: MAQULA ENVE 335 CM3 PET PETALOIDE TRANS 18 GR | B9: =+'Datos M1'!AF9 -> 0 | C9: =+'Datos M2'!AF9 -> 35.466667 | D9: =+'Datos M3'!AF9 -> 44.266667 | E9: =+'Datos M4'!AF9 -> 0 | F9: =+'Datos M5'!AF9 -> 0 | G9: =+'Datos M6'!AF9 -> 54.4 | H9: =+'Datos M7'!AF9 -> 55.866667 | I9: =+'Datos M8'!AF9 -> 64.9 | J9: =+'Datos M9'!AF9 -> 37.8 | K9: =+'Datos M10'!AF9 -> 43.866667
A10: TAPA 28 MM CONICA AMARILLA | B10: =+'Datos M1'!AF10 -> 28.6 | C10: =+'Datos M2'!AF10 -> 71.233333 | D10: =+'Datos M3'!AF10 -> 47.3 | E10: =+'Datos M4'!AF10 -> 0 | F10: =+'Datos M5'!AF10 -> 0 | G10: =+'Datos M6'!AF10 -> 67.833333 | H10: =+'Datos M7'!AF10 -> 47.833333 | I10: =+'Datos M8'!AF10 -> 57.733333 | J10: =+'Datos M9'!AF10 -> 39.266667 | K10: =+'Datos M10'!AF10 -> 59.233333
A11: MAQUILA BOTELLA W240 QUALA | B11: =+'Datos M1'!AF11 -> 33.1 | C11: =+'Datos M2'!AF11 -> 52.766667 | D11: =+'Datos M3'!AF11 -> 40.1 | E11: =+'Datos M4'!AF11 -> 0 | F11: =+'Datos M5'!AF11 -> 0 | G11: =+'Datos M6'!AF11 -> 65.9 | H11: =+'Datos M7'!AF11 -> 37.2 | I11: =+'Datos M8'!AF11 -> 61.133333 | J11: =+'Datos M9'!AF11 -> 48.5 | K11: =+'Datos M10'!AF11 -> 46.366667
A12: PREFORMA SN 20 GRS CRISTAL | B12: =+'Datos M1'!AF12 -> 0 | C12: =+'Datos M2'!AF12 -> 42.533333 | D12: =+'Datos M3'!AF12 -> 51.433333 | E12: =+'Datos M4'!AF12 -> 0 | F12: =+'Datos M5'!AF12 -> 0 | G12: =+'Datos M6'!AF12 -> 74.866667 | H12: =+'Datos M7'!AF12 -> 76.866667 | I12: =+'Datos M8'!AF12 -> 0 | J12: =+'Datos M9'!AF12 -> 32.766667 | K12: =+'Datos M10'!AF12 -> 54.533333
A13: TAPA PP ARO DEEP BLUE 90 ML | B13: =+'Datos M1'!AF13 -> 0 | C13: =+'Datos M2'!AF13 -> 0 | D13: =+'Datos M3'!AF13 -> 60.166667 | E13: =+'Datos M4'!AF13 -> 0 | F13: =+'Datos M5'!AF13 -> 0 | G13: =+'Datos M6'!AF13 -> 54 | H13: =+'Datos M7'!AF13 -> 33.133333 | I13: =+'Datos M8'!AF13 -> 53.133333 | J13: =+'Datos M9'!AF13 -> 29.633333 | K13: =+'Datos M10'!AF13 -> 42.566667
A14: ENVASE 600 BALA ML PET 20 GR | B14: =+'Datos M1'!AF14 -> 0 | C14: =+'Datos M2'!AF14 -> 58.466667 | D14: =+'Datos M3'!AF14 -> 53.533333 | E14: =+'Datos M4'!AF14 -> 0 | F14: =+'Datos M5'!AF14 -> 0 | G14: =+'Datos M6'!AF14 -> 87.733333 | H14: =+'Datos M7'!AF14 -> 61.533333 | I14: =+'Datos M8'!AF14 -> 44.8 | J14: =+'Datos M9'!AF14 -> 64.1 | K14: =+'Datos M10'!AF14 -> 48.2
... A202: TAPA DETERGENTE AZUL PP | B202: =+'Datos M1'!AF202 -> 0 | C202: =+'Datos M2'!AF202 -> 0 | D202: =+'Datos M3'!AF202 -> 63.566667 | E202: =+'Datos M4'!AF202 -> 0 | F202: =+'Datos M5'!AF202 -> 38.466667 | G202: =+'Datos M6'!AF202 -> 40.266667 | H202: =+'Datos M7'!AF202 -> 0 | I202: =+'Datos M8'!AF202 -> 68.933333 | J202: =+'Datos M9'!AF202 -> 44.3 | K202: =+'Datos M10'!AF202 -> 54.366667

Sheet Datos M1
A1: TIEMPO REGISTRADO EN SEGUNDOS POR UNA UNIDAD DE PRODUCTO
A2: PRODUCTO | B2: Registro 1 | C2: Registro 2 | D2: Registro 3 | E2: Registro 4 | F2: Registro 5 | G2: Registro 6 | H2: Registro 7 | I2: Registro 8 | J2: Registro 9 | K2: Registro 10 | L2: Registro 11 | M2: Registro 12 | N2: Registro 13 | O2: Registro 14 | P2: Registro 15 | Q2: Registro 16 | R2: Registro 17 | S2: Registro 18 | T2: Registro 19 | U2: Registro 20 | V2: Registro 21 | W2: Registro 22 | X2: Registro 23 | Y2: Registro 24 | Z2: Registro 25 | AA2: Registro 26 | AB2: Registro 27 | AC2: Registro 28 | AD2: Registro 29 | AE2: Registro 30 | AF2: Promedio
A3: SOBRETAPA SAVILOE 33M | B3: 54 | C3: 87 | D3: 37 | E3: 88 | F3: 34 | G3: 63 | H3: 81 | I3: 16 | J3: 36 | K3: 70 | L3: 41 | M3: 43 | N3: 84 | O3: 33 | P3: 17 | Q3: 85 | R3: 70 | S3: 55 | T3: 23 | U3: 19 | V3: 34 | W3: 59 | X3: 61 | Y3: 39 | Z3: 75 | AA3: 51 | AB3: 23 | AC3: 92 | AD3: 31 | AE3: 29 | AF3: =AVERAGE(B3:AE3) -> 51
A4: MAQUILA ENV 1700 TRANSP CAPRI GEN.NUEVO 41 GR SM | B4: 0 | C4: 0 | D4: 0 | E4: 0 | F4: 0 | G4: 0 | H4: 0 | I4: 0 | J4: 0 | K4: 0 | L4: 0 | M4: 0 | N4: 0 | O4: 0 | P4: 0 | Q4: 0 | R4: 0 | S4: 0 | T4: 0 | U4: 0 | V4: 0 | W4: 0 | X4: 0 | Y4: 0 | Z4: 0 | AA4: 0 | AB4: 0 | AC4: 0 | AD4: 0 | AE4: 0 | AF4: =AVERAGE(B4:AE4) -> 0
A5: MAQUILA ENV 400 CRISTAL 19 GR S.M. PET CAPRI | B5: 17 | C5: 34 | D5: 25 | E5: 25 | F5: 36 | G5: 30 | H5: 38 | I5: 28 | J5: 33 | K5: 26 | L5: 32 | M5: 28 | N5: 13 | O5: 35 | P5: 20 | Q5: 39 | R5: 36 | S5: 17 | T5: 29 | U5: 37 | V5: 40 | W5: 28 | X5: 36 | Y5: 20 | Z5: 11 | AA5: 36 | AB5: 34 | AC5: 16 | AD5: 40 | AE5: 23 | AF5: =AVERAGE(B5:AE5) -> 28.733333
A6: SOBRETAPA VV VERDE SF QUALA | B6: 0 | C6: 20 | D6: 19 | E6: 26 | F6: 18 | G6: 22 | H6: 32 | I6: 16 | J6: 18 | K6: 34 | L6: 18 | M6: 16 | N6: 32 | O6: 20 | P6: 36 | Q6: 23 | R6: 16 | S6: 16 | T6: 35 | U6: 33 | V6: 36 | W6: 33 | X6: 18 | Y6: 29 | Z6: 32 | AA6: 15 | AB6: 35 | AC6: 19 | AD6: 15 | AE6: 24 | AF6: =AVERAGE(B6:AE6) -> 23.533333
A7: MAQUILA ENV 400 CRISTAL 17 GR S.M. PET CAPRI | B7: 0 | C7: 0 | D7: 0 | E7: 0 | F7: 0 | G7: 0 | H7: 0 | I7: 0 | J7: 0 | K7: 0 | L7: 0 | M7: 0 | N7: 0 | O7: 0 | P7: 0 | Q7: 0 | R7: 0 | S7: 0 | T7: 0 | U7: 0 | V7: 0 | W7: 0 | X7: 0 | Y7: 0 | Z7: 0 | AA7: 0 | AB7: 0 | AC7: 0 | AD7: 0 | AE7: 0 | AF7: =AVERAGE(B7:AE7) -> 0
A8: MAQUILA ENV 1000 PET CAPRI NUEVO 31 GR TRANSP SM | B8: 0 | C8: 0 | D8: 0 | E8: 0 | F8: 0 | G8: 0 | H8: 0 | I8: 0 | J8: 0 | K8: 0 | L8: 0 | M8: 0 | N8: 0 | O8: 0 | P8: 0 | Q8: 0 | R8: 0 | S8: 0 | T8: 0 | U8: 0 | V8: 0 | W8: 0 | X8: 0 | Y8: 0 | Z8: 0 | AA8: 0 | AB8: 0 | AC8: 0 | AD8: 0 | AE8: 0 | AF8: =AVERAGE(B8:AE8) -> 0
A9: MAQULA ENVE 335 CM3 PET PETALOIDE TRANS 18 GR | B9: 0 | C9: 0 | D9: 0 | E9: 0 | F9: 0 | G9: 0 | H9: 0 | I9: 0 | J9: 0 | K9: 0 | L9: 0 | M9: 0 | N9: 0 | O9: 0 | P9: 0 | Q9: 0 | R9: 0 | S9: 0 | T9: 0 | U9: 0 | V9: 0 | W9: 0 | X9: 0 | Y9: 0 | Z9: 0 | AA9: 0 | AB9: 0 | AC9: 0 | AD9: 0 | AE9: 0 | AF9: =AVERAGE(B9:AE9) -> 0
A10: TAPA 28 MM CONICA AMARILLA | B10: 41 | C10: 16 | D10: 43 | E10: 14 | F10: 32 | G10: 34 | H10: 23 | I10: 16 | J10: 33 | K10: 42 | L10: 37 | M10: 15 | N10: 10 | O10: 29 | P10: 32 | Q10: 45 | R10: 47 | S10: 26 | T10: 43 | U10: 36 | V10: 10 | W10: 25 | X10: 37 | Y10: 15 | Z10: 16 | AA10: 43 | AB10: 39 | AC10: 24 | AD10: 14 | AE10: 21 | AF10: =AVERAGE(B10:AE10) -> 28.6
A11: MAQUILA BOTELLA W240 QUALA | B11: 32 | C11: 23 | D11: 27 | E11: 49 | F11: 52 | G11: 40 | H11: 37 | I11: 27 | J11: 34 | K11: 43 | L11: 24 | M11: 31 | N11: 48 | O11: 28 | P11: 50 | Q11: 43 | R11: 41 | S11: 29 | T11: 28 | U11: 20 | V11: 26 | W11: 33 | X11: 25 | Y11: 19 | Z11: 22 | AA11: 37 | AB11: 33 | AC11: 51 | AD11: 19 | AE11: 22 | AF11: =AVERAGE(B11:AE11) -> 33.1
A12: PREFORMA SN 20 GRS CRISTAL | B12: 0 | C12: 0 | D12: 0 | E12: 0 | F12: 0 | G12: 0 | H12: 0 | I12: 0 | J12: 0 | K12: 0 | L12: 0 | M12: 0 | N12: 0 | O12: 0 | P12: 0 | Q12: 0 | R12: 0 | S12: 0 | T12: 0 | U12: 0 | V12: 0 | W12: 0 | X12: 0 | Y12: 0 | Z12: 0 | AA12: 0 | AB12: 0 | AC12: 0 | AD12: 0 | AE12: 0 | AF12: =AVERAGE(B12:AE12) -> 0
A13: TAPA PP ARO DEEP BLUE 90 ML | B13: 0 | C13: 0 | D13: 0 | E13: 0 | F13: 0 | G13: 0 | H13: 0 | I13: 0 | J13: 0 | K13: 0 | L13: 0 | M13: 0 | N13: 0 | O13: 0 | P13: 0 | Q13: 0 | R13: 0 | S13: 0 | T13: 0 | U13: 0 | V13: 0 | W13: 0 | X13: 0 | Y13: 0 | Z13: 0 | AA13: 0 | AB13: 0 | AC13: 0 | AD13: 0 | AE13: 0 | AF13: =AVERAGE(B13:AE13) -> 0
A14: ENVASE 600 BALA ML PET 20 GR | B14: 0 | C14: 0 | D14: 0 | E14: 0 | F14: 0 | G14: 0 | H14: 0 | I14: 0 | J14: 0 | K14: 0 | L14: 0 | M14: 0 | N14: 0 | O14: 0 | P14: 0 | Q14: 0 | R14: 0 | S14: 0 | T14: 0 | U14: 0 | V14: 0 | W14: 0 | X14: 0 | Y14: 0 | Z14: 0 | AA14: 0 | AB14: 0 | AC14: 0 | AD14: 0 | AE14: 0 | AF14: =AVERAGE(B14:AE14) -> 0
... A202: TAPA DETERGENTE AZUL PP | B202: 0 | C202: 0 | D202: 0 | E202: 0 | F202: 0 | G202: 0 | H202: 0 | I202: 0 | J202: 0 | K202: 0 | L202: 0 | M202: 0 | N202: 0 | O202: 0 | P202: 0 | Q202: 0 | R202: 0 | S202: 0 | T202: 0 | U202: 0 | V202: 0 | W202: 0 | X202: 0 | Y202: 0 | Z202: 0 | AA202: 0 | AB202: 0 | AC202: 0 | AD202: 0 | AE202: 0 | AF202: =AVERAGE(B202:AE202) -> 0

Sheet Datos M2
A1: TIEMPO REGISTRADO EN SEGUNDOS POR UNA UNIDAD DE PRODUCTO
A2: PRODUCTO | B2: Registro 1 | C2: Registro 2 | D2: Registro 3 | E2: Registro 4 | F2: Registro 5 | G2: Registro 6 | H2: Registro 7 | I2: Registro 8 | J2: Registro 9 | K2: Registro 10 | L2: Registro 11 | M2: Registro 12 | N2: Registro 13 | O2: Registro 14 | P2: Registro 15 | Q2: Registro 16 | R2: Registro 17 | S2: Registro 18 | T2: Registro 19 | U2: Registro 20 | V2: Registro 21 | W2: Registro 22 | X2: Registro 23 | Y2: Registro 24 | Z2: Registro 25 | AA2: Registro 26 | AB2: Registro 27 | AC2: Registro 28 | AD2: Registro 29 | AE2: Registro 30 | AF2: Promedio
A3: SOBRETAPA SAVILOE 33M | B3: 44 | C3: 61 | D3: 58 | E3: 48 | F3: 76 | G3: 50 | H3: 24 | I3: 50 | J3: 22 | K3: 33 | L3: 60 | M3: 15 | N3: 25 | O3: 30 | P3: 18 | Q3: 34 | R3: 25 | S3: 22 | T3: 22 | U3: 12 | V3: 33 | W3: 73 | X3: 21 | Y3: 21 | Z3: 19 | AA3: 19 | AB3: 18 | AC3: 48 | AD3: 176 | AE3: 20 | AF3: =AVERAGE(B3:AE3) -> 39.233333
A4: MAQUILA ENV 1700 TRANSP CAPRI GEN.NUEVO 41 GR SM | B4: 0 | C4: 0 | D4: 0 | E4: 0 | F4: 0 | G4: 0 | H4: 0 | I4: 0 | J4: 0 | K4: 0 | L4: 0 | M4: 0 | N4: 0 | O4: 0 | P4: 0 | Q4: 0 | R4: 0 | S4: 0 | T4: 0 | U4: 0 | V4: 0 | W4: 0 | X4: 0 | Y4: 0 | Z4: 0 | AA4: 0 | AB4: 0 | AC4: 0 | AD4: 0 | AE4: 0 | AF4: =AVERAGE(B4:AE4) -> 0
A5: MAQUILA ENV 400 CRISTAL 19 GR S.M. PET CAPRI | B5: 20 | C5: 39 | D5: 103 | E5: 76 | F5: 41 | G5: 23 | H5: 41 | I5: 24 | J5: 45 | K5: 39 | L5: 65 | M5: 62 | N5: 94 | O5: 25 | P5: 161 | Q5: 33 | R5: 142 | S5: 38 | T5: 51 | U5: 31 | V5: 18 | W5: 45 | X5: 44 | Y5: 25 | Z5: 14 | AA5: 57 | AB5: 47 | AC5: 84 | AD5: 38 | AE5: 23 | AF5: =AVERAGE(B5:AE5) -> 51.6
A6: SOBRETAPA VV VERDE SF QUALA | B6: 33 | C6: 26 | D6: 23 | E6: 39 | F6: 20 | G6: 33 | H6: 41 | I6: 36 | J6: 69 | K6: 28 | L6: 19 | M6: 83 | N6: 21 | O6: 53 | P6: 40 | Q6: 12 | R6: 40 | S6: 27 | T6: 67 | U6: 42 | V6: 60 | W6: 148 | X6: 25 | Y6: 40 | Z6: 47 | AA6: 150 | AB6: 37 | AC6: 218 | AD6: 57 | AE6: 14 | AF6: =AVERAGE(B6:AE6) -> 51.6
A7: MAQUILA ENV 400 CRISTAL 17 GR S.M. PET CAPRI | B7: 21 | C7: 62 | D7: 84 | E7: 61 | F7: 26 | G7: 99 | H7: 26 | I7: 88 | J7: 111 | K7: 22 | L7: 47 | M7: 44 | N7: 126 | O7: 82 | P7: 40 | Q7: 53 | R7: 118 | S7: 52 | T7: 26 | U7: 53 | V7: 15 | W7: 19 | X7: 45 | Y7: 22 | Z7: 37 | AA7: 76 | AB7: 25 | AC7: 20 | AD7: 149 | AE7: 24 | AF7: =AVERAGE(B7:AE7) -> 55.766667
A8: MAQUILA ENV 1000 PET CAPRI NUEVO 31 GR TRANSP SM | B8: 0 | C8: 0 | D8: 0 | E8: 0 | F8: 0 | G8: 0 | H8: 0 | I8: 0 | J8: 0 | K8: 0 | L8: 0 | M8: 0 | N8: 0 | O8: 0 | P8: 0 | Q8: 0 | R8: 0 | S8: 0 | T8: 0 | U8: 0 | V8: 0 | W8: 0 | X8: 0 | Y8: 0 | Z8: 0 | AA8: 0 | AB8: 0 | AC8: 0 | AD8: 0 | AE8: 0 | AF8: =AVERAGE(B8:AE8) -> 0
A9: MAQULA ENVE 335 CM3 PET PETALOIDE TRANS 18 GR | B9: 32 | C9: 65 | D9: 32 | E9: 55 | F9: 13 | G9: 14 | H9: 18 | I9: 16 | J9: 24 | K9: 53 | L9: 15 | M9: 18 | N9: 14 | O9: 22 | P9: 45 | Q9: 46 | R9: 21 | S9: 70 | T9: 13 | U9: 150 | V9: 27 | W9: 22 | X9: 53 | Y9: 49 | Z9: 22 | AA9: 32 | AB9: 15 | AC9: 63 | AD9: 14 | AE9: 31 | AF9: =AVERAGE(B9:AE9) -> 35.466667
A10: TAPA 28 MM CONICA AMARILLA | B10: 151 | C10: 69 | D10: 21 | E10: 54 | F10: 84 | G10: 27 | H10: 16 | I10: 26 | J10: 20 | K10: 90 | L10: 47 | M10: 54 | N10: 68 | O10: 36 | P10: 34 | Q10: 44 | R10: 56 | S10: 94 | T10: 52 | U10: 88 | V10: 142 | W10: 46 | X10: 145 | Y10: 21 | Z10: 31 | AA10: 17 | AB10: 155 | AC10: 323 | AD10: 61 | AE10: 65 | AF10: =AVERAGE(B10:AE10) -> 71.233333
A11: MAQUILA BOTELLA W240 QUALA | B11: 66 | C11: 39 | D11: 26 | E11: 24 | F11: 42 | G11: 68 | H11: 13 | I11: 74 | J11: 62 | K11: 69 | L11: 111 | M11: 24 | N11: 79 | O11: 28 | P11: 14 | Q11: 50 | R11: 27 | S11: 56 | T11: 47 | U11: 29 | V11: 57 | W11: 34 | X11: 25 | Y11: 42 | Z11: 121 | AA11: 17 | AB11: 27 | AC11: 125 | AD11: 125 | AE11: 62 | AF11: =AVERAGE(B11:AE11) -> 52.766667
A12: PREFORMA SN 20 GRS CRISTAL | B12: 39 | C12: 61 | D12: 23 | E12: 22 | F12: 70 | G12: 25 | H12: 13 | I12: 104 | J12: 17 | K12: 46 | L12: 70 | M12: 32 | N12: 30 | O12: 13 | P12: 31 | Q12: 49 | R12: 29 | S12: 13 | T12: 26 | U12: 40 | V12: 65 | W12: 65 | X12: 33 | Y12: 63 | Z12: 49 | AA12: 31 | AB12: 78 | AC12: 21 | AD12: 60 | AE12: 58 | AF12: =AVERAGE(B12:AE12) -> 42.533333
A13: TAPA PP ARO DEEP BLUE 90 ML | B13: 0 | C13: 0 | D13: 0 | E13: 0 | F13: 0 | G13: 0 | H13: 0 | I13: 0 | J13: 0 | K13: 0 | L13: 0 | M13: 0 | N13: 0 | O13: 0 | P13: 0 | Q13: 0 | R13: 0 | S13: 0 | T13: 0 | U13: 0 | V13: 0 | W13: 0 | X13: 0 | Y13: 0 | Z13: 0 | AA13: 0 | AB13: 0 | AC13: 0 | AD13: 0 | AE13: 0 | AF13: =AVERAGE(B13:AE13) -> 0
A14: ENVASE 600 BALA ML PET 20 GR | B14: 163 | C14: 25 | D14: 57 | E14: 62 | F14: 56 | G14: 44 | H14: 36 | I14: 117 | J14: 17 | K14: 45 | L14: 23 | M14: 47 | N14: 90 | O14: 93 | P14: 22 | Q14: 108 | R14: 68 | S14: 30 | T14: 63 | U14: 63 | V14: 158 | W14: 31 | X14: 57 | Y14: 30 | Z14: 17 | AA14: 83 | AB14: 12 | AC14: 50 | AD14: 56 | AE14: 31 | AF14: =AVERAGE(B14:AE14) -> 58.466667
... A202: TAPA DETERGENTE AZUL PP | B202: 0 | C202: 0 | D202: 0 | E202: 0 | F202: 0 | G202: 0 | H202: 0 | I202: 0 | J202: 0 | K202: 0 | L202: 0 | M202: 0 | N202: 0 | O202: 0 | P202: 0 | Q202: 0 | R202: 0 | S202: 0 | T202: 0 | U202: 0 | V202: 0 | W202: 0 | X202: 0 | Y202: 0 | Z202: 0 | AA202: 0 | AB202: 0 | AC202: 0 | AD202: 0 | AE202: 0 | AF202: =AVERAGE(B202:AE202) -> 0
B203: 15 | C203: 15 | D203: 22 | E203: 40 | F203: 19 | G203: 45 | H203: 35 | I203: 38 | J203: 52 | K203: 55 | L203: 54 | M203: 126 | N203: 17 | O203: 40 | P203: 62 | Q203: 83 | R203: 109 | S203: 43 | T203: 71 | U203: 59 | V203: 103 | W203: 19 | X203: 39 | Y203: 109 | Z203: 31 | AA203: 83 | AB203: 24 | AC203: 143 | AD203: 49 | AE203: 82

Sheet Datos M3
A1: TIEMPO REGISTRADO EN SEGUNDOS POR UNA UNIDAD DE PRODUCTO
A2: PRODUCTO | B2: Registro 1 | C2: Registro 2 | D2: Registro 3 | E2: Registro 4 | F2: Registro 5 | G2: Registro 6 | H2: Registro 7 | I2: Registro 8 | J2: Registro 9 | K2: Registro 10 | L2: Registro 11 | M2: Registro 12 | N2: Registro 13 | O2: Registro 14 | P2: Registro 15 | Q2: Registro 16 | R2: Registro 17 | S2: Registro 18 | T2: Registro 19 | U2: Registro 20 | V2: Registro 21 | W2: Registro 22 | X2: Registro 23 | Y2: Registro 24 | Z2: Registro 25 | AA2: Registro 26 | AB2: Registro 27 | AC2: Registro 28 | AD2: Registro 29 | AE2: Registro 30 | AF2: Promedio
A3: SOBRETAPA SAVILOE 33M | B3: 37 | C3: 37 | D3: 16 | E3: 75 | F3: 130 | G3: 102 | H3: 86 | I3: 15 | J3: 31 | K3: 100 | L3: 42 | M3: 33 | N3: 57 | O3: 141 | P3: 116 | Q3: 12 | R3: 90 | S3: 153 | T3: 46 | U3: 18 | V3: 42 | W3: 27 | X3: 214 | Y3: 19 | Z3: 138 | AA3: 50 | AB3: 57 | AC3: 17 | AD3: 36 | AE3: 150 | AF3: =AVERAGE(B3:AE3) -> 69.566667
A4: MAQUILA ENV 1700 TRANSP CAPRI GEN.NUEVO 41 GR SM | B4: 24 | C4: 24 | D4: 26 | E4: 38 | F4: 14 | G4: 94 | H4: 42 | I4: 59 | J4: 18 | K4: 33 | L4: 44 | M4: 23 | N4: 21 | O4: 26 | P4: 25 | Q4: 40 | R4: 24 | S4: 35 | T4: 66 | U4: 59 | V4: 68 | W4: 31 | X4: 78 | Y4: 101 | Z4: 29 | AA4: 12 | AB4: 19 | AC4: 21 | AD4: 53 | AE4: 28 | AF4: =AVERAGE(B4:AE4) -> 39.166667
A5: MAQUILA ENV 400 CRISTAL 19 GR S.M. PET CAPRI | B5: 20 | C5: 122 | D5: 50 | E5: 74 | F5: 86 | G5: 72 | H5: 18 | I5: 41 | J5: 24 | K5: 43 | L5: 37 | M5: 13 | N5: 150 | O5: 33 | P5: 23 | Q5: 18 | R5: 14 | S5: 109 | T5: 14 | U5: 48 | V5: 17 | W5: 23 | X5: 42 | Y5: 13 | Z5: 54 | AA5: 52 | AB5: 35 | AC5: 23 | AD5: 99 | AE5: 84 | AF5: =AVERAGE(B5:AE5) -> 48.366667
A6: SOBRETAPA VV VERDE SF QUALA | B6: 36 | C6: 14 | D6: 12 | E6: 19 | F6: 113 | G6: 16 | H6: 32 | I6: 47 | J6: 16 | K6: 42 | L6: 24 | M6: 23 | N6: 268 | O6: 244 | P6: 33 | Q6: 109 | R6: 42 | S6: 100 | T6: 34 | U6: 12 | V6: 13 | W6: 64 | X6: 73 | Y6: 122 | Z6: 18 | AA6: 129 | AB6: 13 | AC6: 12 | AD6: 15 | AE6: 18 | AF6: =AVERAGE(B6:AE6) -> 57.1
A7: MAQUILA ENV 400 CRISTAL 17 GR S.M. PET CAPRI | B7: 37 | C7: 172 | D7: 73 | E7: 46 | F7: 21 | G7: 20 | H7: 63 | I7: 60 | J7: 21 | K7: 110 | L7: 63 | M7: 44 | N7: 60 | O7: 12 | P7: 15 | Q7: 35 | R7: 24 | S7: 27 | T7: 75 | U7: 116 | V7: 27 | W7: 159 | X7: 46 | Y7: 32 | Z7: 45 | AA7: 13 | AB7: 29 | AC7: 22 | AD7: 105 | AE7: 46 | AF7: =AVERAGE(B7:AE7) -> 53.933333
A8: MAQUILA ENV 1000 PET CAPRI NUEVO 31 GR TRANSP SM | B8: 50 | C8: 15 | D8: 50 | E8: 99 | F8: 34 | G8: 47 | H8: 71 | I8: 177 | J8: 53 | K8: 95 | L8: 64 | M8: 43 | N8: 165 | O8: 55 | P8: 23 | Q8: 43 | R8: 63 | S8: 96 | T8: 30 | U8: 181 | V8: 96 | W8: 33 | X8: 22 | Y8: 71 | Z8: 12 | AA8: 56 | AB8: 229 | AC8: 51 | AD8: 18 | AE8: 48 | AF8: =AVERAGE(B8:AE8) -> 69.666667
A9: MAQULA ENVE 335 CM3 PET PETALOIDE TRANS 18 GR | B9: 30 | C9: 115 | D9: 17 | E9: 15 | F9: 28 | G9: 30 | H9: 20 | I9: 27 | J9: 77 | K9: 22 | L9: 48 | M9: 61 | N9: 25 | O9: 14 | P9: 28 | Q9: 15 | R9: 37 | S9: 75 | T9: 46 | U9: 144 | V9: 22 | W9: 32 | X9: 31 | Y9: 48 | Z9: 12 | AA9: 79 | AB9: 17 | AC9: 121 | AD9: 36 | AE9: 56 | AF9: =AVERAGE(B9:AE9) -> 44.266667
A10: TAPA 28 MM CONICA AMARILLA | B10: 15 | C10: 106 | D10: 64 | E10: 22 | F10: 38 | G10: 39 | H10: 45 | I10: 88 | J10: 25 | K10: 14 | L10: 40 | M10: 137 | N10: 38 | O10: 50 | P10: 16 | Q10: 23 | R10: 92 | S10: 38 | T10: 38 | U10: 49 | V10: 62 | W10: 58 | X10: 106 | Y10: 25 | Z10: 44 | AA10: 31 | AB10: 12 | AC10: 23 | AD10: 15 | AE10: 66 | AF10: =AVERAGE(B10:AE10) -> 47.3
A11: MAQUILA BOTELLA W240 QUALA | B11: 36 | C11: 79 | D11: 26 | E11: 73 | F11: 42 | G11: 29 | H11: 21 | I11: 17 | J11: 14 | K11: 17 | L11: 14 | M11: 24 | N11: 26 | O11: 13 | P11: 20 | Q11: 28 | R11: 36 | S11: 24 | T11: 101 | U11: 13 | V11: 16 | W11: 49 | X11: 12 | Y11: 85 | Z11: 67 | AA11: 110 | AB11: 25 | AC11: 22 | AD11: 60 | AE11: 104 | AF11: =AVERAGE(B11:AE11) -> 40.1
A12: PREFORMA SN 20 GRS CRISTAL | B12: 12 | C12: 45 | D12: 70 | E12: 75 | F12: 31 | G12: 52 | H12: 72 | I12: 20 | J12: 40 | K12: 54 | L12: 237 | M12: 13 | N12: 28 | O12: 103 | P12: 37 | Q12: 19 | R12: 87 | S12: 46 | T12: 117 | U12: 92 | V12: 17 | W12: 23 | X12: 23 | Y12: 20 | Z12: 17 | AA12: 49 | AB12: 39 | AC12: 44 | AD12: 35 | AE12: 26 | AF12: =AVERAGE(B12:AE12) -> 51.433333
A13: TAPA PP ARO DEEP BLUE 90 ML | B13: 27 | C13: 15 | D13: 36 | E13: 21 | F13: 22 | G13: 13 | H13: 82 | I13: 35 | J13: 49 | K13: 69 | L13: 213 | M13: 141 | N13: 56 | O13: 23 | P13: 109 | Q13: 47 | R13: 34 | S13: 23 | T13: 24 | U13: 82 | V13: 70 | W13: 34 | X13: 23 | Y13: 149 | Z13: 59 | AA13: 38 | AB13: 58 | AC13: 111 | AD13: 36 | AE13: 106 | AF13: =AVERAGE(B13:AE13) -> 60.166667
A14: ENVASE 600 BALA ML PET 20 GR | B14: 13 | C14: 51 | D14: 23 | E14: 136 | F14: 40 | G14: 50 | H14: 20 | I14: 31 | J14: 103 | K14: 73 | L14: 42 | M14: 24 | N14: 250 | O14: 81 | P14: 77 | Q14: 29 | R14: 84 | S14: 16 | T14: 37 | U14: 25 | V14: 22 | W14: 74 | X14: 66 | Y14: 48 | Z14: 34 | AA14: 30 | AB14: 18 | AC14: 14 | AD14: 72 | AE14: 23 | AF14: =AVERAGE(B14:AE14) -> 53.533333
... A202: TAPA DETERGENTE AZUL PP | B202: 26 | C202: 167 | D202: 48 | E202: 27 | F202: 147 | G202: 136 | H202: 52 | I202: 25 | J202: 12 | K202: 36 | L202: 104 | M202: 64 | N202: 147 | O202: 37 | P202: 13 | Q202: 169 | R202: 19 | S202: 15 | T202: 14 | U202: 71 | V202: 59 | W202: 25 | X202: 27 | Y202: 78 | Z202: 68 | AA202: 12 | AB202: 14 | AC202: 91 | AD202: 150 | AE202: 54 | AF202: =AVERAGE(B202:AE202) -> 63.566667
B203: 0 | C203: 0 | D203: 0 | E203: 0 | F203: 0 | G203: 0 | H203: 0 | I203: 0 | J203: 0 | K203: 0 | L203: 0 | M203: 0 | N203: 0 | O203: 0 | P203: 0 | Q203: 0 | R203: 0 | S203: 0 | T203: 0 | U203: 0 | V203: 0 | W203: 0 | X203: 0 | Y203: 0 | Z203: 0 | AA203: 0 | AB203: 0 | AC203: 0 | AD203: 0 | AE203: 0

Sheet Datos M4
A1: TIEMPO REGISTRADO EN SEGUNDOS POR UNA UNIDAD DE PRODUCTO
A2: PRODUCTO | B2: Registro 1 | C2: Registro 2 | D2: Registro 3 | E2: Registro 4 | F2: Registro 5 | G2: Registro 6 | H2: Registro 7 | I2: Registro 8 | J2: Registro 9 | K2: Registro 10 | L2: Registro 11 | M2: Registro 12 | N2: Registro 13 | O2: Registro 14 | P2: Registro 15 | Q2: Registro 16 | R2: Registro 17 | S2: Registro 18 | T2: Registro 19 | U2: Registro 20 | V2: Registro 21 | W2: Registro 22 | X2: Registro 23 | Y2: Registro 24 | Z2: Registro 25 | AA2: Registro 26 | AB2: Registro 27 | AC2: Registro 28 | AD2: Registro 29 | AE2: Registro 30 | AF2: Promedio
A3: SOBRETAPA SAVILOE 33M | B3: 0 | C3: 0 | D3: 0 | E3: 0 | F3: 0 | G3: 0 | H3: 0 | I3: 0 | J3: 0 | K3: 0 | L3: 0 | M3: 0 | N3: 0 | O3: 0 | P3: 0 | Q3: 0 | R3: 0 | S3: 0 | T3: 0 | U3: 0 | V3: 0 | W3: 0 | X3: 0 | Y3: 0 | Z3: 0 | AA3: 0 | AB3: 0 | AC3: 0 | AD3: 0 | AE3: 0 | AF3: =AVERAGE(B3:AE3) -> 0
A4: MAQUILA ENV 1700 TRANSP CAPRI GEN.NUEVO 41 GR SM | B4: 0 | C4: 0 | D4: 0 | E4: 0 | F4: 0 | G4: 0 | H4: 0 | I4: 0 | J4: 0 | K4: 0 | L4: 0 | M4: 0 | N4: 0 | O4: 0 | P4: 0 | Q4: 0 | R4: 0 | S4: 0 | T4: 0 | U4: 0 | V4: 0 | W4: 0 | X4: 0 | Y4: 0 | Z4: 0 | AA4: 0 | AB4: 0 | AC4: 0 | AD4: 0 | AE4: 0 | AF4: =AVERAGE(B4:AE4) -> 0
A5: MAQUILA ENV 400 CRISTAL 19 GR S.M. PET CAPRI | B5: 0 | C5: 0 | D5: 0 | E5: 0 | F5: 0 | G5: 0 | H5: 0 | I5: 0 | J5: 0 | K5: 0 | L5: 0 | M5: 0 | N5: 0 | O5: 0 | P5: 0 | Q5: 0 | R5: 0 | S5: 0 | T5: 0 | U5: 0 | V5: 0 | W5: 0 | X5: 0 | Y5: 0 | Z5: 0 | AA5: 0 | AB5: 0 | AC5: 0 | AD5: 0 | AE5: 0 | AF5: =AVERAGE(B5:AE5) -> 0
A6: SOBRETAPA VV VERDE SF QUALA | B6: 0 | C6: 0 | D6: 0 | E6: 0 | F6: 0 | G6: 0 | H6: 0 | I6: 0 | J6: 0 | K6: 0 | L6: 0 | M6: 0 | N6: 0 | O6: 0 | P6: 0 | Q6: 0 | R6: 0 | S6: 0 | T6: 0 | U6: 0 | V6: 0 | W6: 0 | X6: 0 | Y6: 0 | Z6: 0 | AA6: 0 | AB6: 0 | AC6: 0 | AD6: 0 | AE6: 0 | AF6: =AVERAGE(B6:AE6) -> 0
A7: MAQUILA ENV 400 CRISTAL 17 GR S.M. PET CAPRI | B7: 0 | C7: 0 | D7: 0 | E7: 0 | F7: 0 | G7: 0 | H7: 0 | I7: 0 | J7: 0 | K7: 0 | L7: 0 | M7: 0 | N7: 0 | O7: 0 | P7: 0 | Q7: 0 | R7: 0 | S7: 0 | T7: 0 | U7: 0 | V7: 0 | W7: 0 | X7: 0 | Y7: 0 | Z7: 0 | AA7: 0 | AB7: 0 | AC7: 0 | AD7: 0 | AE7: 0 | AF7: =AVERAGE(B7:AE7) -> 0
A8: MAQUILA ENV 1000 PET CAPRI NUEVO 31 GR TRANSP SM | B8: 0 | C8: 0 | D8: 0 | E8: 0 | F8: 0 | G8: 0 | H8: 0 | I8: 0 | J8: 0 | K8: 0 | L8: 0 | M8: 0 | N8: 0 | O8: 0 | P8: 0 | Q8: 0 | R8: 0 | S8: 0 | T8: 0 | U8: 0 | V8: 0 | W8: 0 | X8: 0 | Y8: 0 | Z8: 0 | AA8: 0 | AB8: 0 | AC8: 0 | AD8: 0 | AE8: 0 | AF8: =AVERAGE(B8:AE8) -> 0
A9: MAQULA ENVE 335 CM3 PET PETALOIDE TRANS 18 GR | B9: 0 | C9: 0 | D9: 0 | E9: 0 | F9: 0 | G9: 0 | H9: 0 | I9: 0 | J9: 0 | K9: 0 | L9: 0 | M9: 0 | N9: 0 | O9: 0 | P9: 0 | Q9: 0 | R9: 0 | S9: 0 | T9: 0 | U9: 0 | V9: 0 | W9: 0 | X9: 0 | Y9: 0 | Z9: 0 | AA9: 0 | AB9: 0 | AC9: 0 | AD9: 0 | AE9: 0 | AF9: =AVERAGE(B9:AE9) -> 0
A10: TAPA 28 MM CONICA AMARILLA | B10: 0 | C10: 0 | D10: 0 | E10: 0 | F10: 0 | G10: 0 | H10: 0 | I10: 0 | J10: 0 | K10: 0 | L10: 0 | M10: 0 | N10: 0 | O10: 0 | P10: 0 | Q10: 0 | R10: 0 | S10: 0 | T10: 0 | U10: 0 | V10: 0 | W10: 0 | X10: 0 | Y10: 0 | Z10: 0 | AA10: 0 | AB10: 0 | AC10: 0 | AD10: 0 | AE10: 0 | AF10: =AVERAGE(B10:AE10) -> 0
A11: MAQUILA BOTELLA W240 QUALA | B11: 0 | C11: 0 | D11: 0 | E11: 0 | F11: 0 | G11: 0 | H11: 0 | I11: 0 | J11: 0 | K11: 0 | L11: 0 | M11: 0 | N11: 0 | O11: 0 | P11: 0 | Q11: 0 | R11: 0 | S11: 0 | T11: 0 | U11: 0 | V11: 0 | W11: 0 | X11: 0 | Y11: 0 | Z11: 0 | AA11: 0 | AB11: 0 | AC11: 0 | AD11: 0 | AE11: 0 | AF11: =AVERAGE(B11:AE11) -> 0
A12: PREFORMA SN 20 GRS CRISTAL | B12: 0 | C12: 0 | D12: 0 | E12: 0 | F12: 0 | G12: 0 | H12: 0 | I12: 0 | J12: 0 | K12: 0 | L12: 0 | M12: 0 | N12: 0 | O12: 0 | P12: 0 | Q12: 0 | R12: 0 | S12: 0 | T12: 0 | U12: 0 | V12: 0 | W12: 0 | X12: 0 | Y12: 0 | Z12: 0 | AA12: 0 | AB12: 0 | AC12: 0 | AD12: 0 | AE12: 0 | AF12: =AVERAGE(B12:AE12) -> 0
A13: TAPA PP ARO DEEP BLUE 90 ML | B13: 0 | C13: 0 | D13: 0 | E13: 0 | F13: 0 | G13: 0 | H13: 0 | I13: 0 | J13: 0 | K13: 0 | L13: 0 | M13: 0 | N13: 0 | O13: 0 | P13: 0 | Q13: 0 | R13: 0 | S13: 0 | T13: 0 | U13: 0 | V13: 0 | W13: 0 | X13: 0 | Y13: 0 | Z13: 0 | AA13: 0 | AB13: 0 | AC13: 0 | AD13: 0 | AE13: 0 | AF13: =AVERAGE(B13:AE13) -> 0
A14: ENVASE 600 BALA ML PET 20 GR | B14: 0 | C14: 0 | D14: 0 | E14: 0 | F14: 0 | G14: 0 | H14: 0 | I14: 0 | J14: 0 | K14: 0 | L14: 0 | M14: 0 | N14: 0 | O14: 0 | P14: 0 | Q14: 0 | R14: 0 | S14: 0 | T14: 0 | U14: 0 | V14: 0 | W14: 0 | X14: 0 | Y14: 0 | Z14: 0 | AA14: 0 | AB14: 0 | AC14: 0 | AD14: 0 | AE14: 0 | AF14: =AVERAGE(B14:AE14) -> 0
... A202: TAPA DETERGENTE AZUL PP | B202: 0 | C202: 0 | D202: 0 | E202: 0 | F202: 0 | G202: 0 | H202: 0 | I202: 0 | J202: 0 | K202: 0 | L202: 0 | M202: 0 | N202: 0 | O202: 0 | P202: 0 | Q202: 0 | R202: 0 | S202: 0 | T202: 0 | U202: 0 | V202: 0 | W202: 0 | X202: 0 | Y202: 0 | Z202: 0 | AA202: 0 | AB202: 0 | AC202: 0 | AD202: 0 | AE202: 0 | AF202: =AVERAGE(B202:AE202) -> 0
B203: 98 | C203: 73 | D203: 50 | E203: 22 | F203: 42 | G203: 85 | H203: 26 | I203: 48 | J203: 14 | K203: 13 | L203: 13 | M203: 42 | N203: 44 | O203: 31 | P203: 39 | Q203: 39 | R203: 17 | S203: 12 | T203: 24 | U203: 30 | V203: 13 | W203: 19 | X203: 39 | Y203: 16 | Z203: 110 | AA203: 14 | AB203: 13 | AC203: 15 | AD203: 38 | AE203: 39

Sheet Datos M5
A1: TIEMPO REGISTRADO EN SEGUNDOS POR UNA UNIDAD DE PRODUCTO
A2: PRODUCTO | B2: Registro 1 | C2: Registro 2 | D2: Registro 3 | E2: Registro 4 | F2: Registro 5 | G2: Registro 6 | H2: Registro 7 | I2: Registro 8 | J2: Registro 9 | K2: Registro 10 | L2: Registro 11 | M2: Registro 12 | N2: Registro 13 | O2: Registro 14 | P2: Registro 15 | Q2: Registro 16 | R2: Registro 17 | S2: Registro 18 | T2: Registro 19 | U2: Registro 20 | V2: Registro 21 | W2: Registro 22 | X2: Registro 23 | Y2: Registro 24 | Z2: Registro 25 | AA2: Registro 26 | AB2: Registro 27 | AC2: Registro 28 | AD2: Registro 29 | AE2: Registro 30 | AF2: Promedio
A3: SOBRETAPA SAVILOE 33M | B3: 0 | C3: 0 | D3: 0 | E3: 0 | F3: 0 | G3: 0 | H3: 0 | I3: 0 | J3: 0 | K3: 0 | L3: 0 | M3: 0 | N3: 0 | O3: 0 | P3: 0 | Q3: 0 | R3: 0 | S3: 0 | T3: 0 | U3: 0 | V3: 0 | W3: 0 | X3: 0 | Y3: 0 | Z3: 0 | AA3: 0 | AB3: 0 | AC3: 0 | AD3: 0 | AE3: 0 | AF3: =AVERAGE(B3:AE3) -> 0
A4: MAQUILA ENV 1700 TRANSP CAPRI GEN.NUEVO 41 GR SM | B4: 0 | C4: 0 | D4: 0 | E4: 0 | F4: 0 | G4: 0 | H4: 0 | I4: 0 | J4: 0 | K4: 0 | L4: 0 | M4: 0 | N4: 0 | O4: 0 | P4: 0 | Q4: 0 | R4: 0 | S4: 0 | T4: 0 | U4: 0 | V4: 0 | W4: 0 | X4: 0 | Y4: 0 | Z4: 0 | AA4: 0 | AB4: 0 | AC4: 0 | AD4: 0 | AE4: 0 | AF4: =AVERAGE(B4:AE4) -> 0
A5: MAQUILA ENV 400 CRISTAL 19 GR S.M. PET CAPRI | B5: 0 | C5: 0 | D5: 0 | E5: 0 | F5: 0 | G5: 0 | H5: 0 | I5: 0 | J5: 0 | K5: 0 | L5: 0 | M5: 0 | N5: 0 | O5: 0 | P5: 0 | Q5: 0 | R5: 0 | S5: 0 | T5: 0 | U5: 0 | V5: 0 | W5: 0 | X5: 0 | Y5: 0 | Z5: 0 | AA5: 0 | AB5: 0 | AC5: 0 | AD5: 0 | AE5: 0 | AF5: =AVERAGE(B5:AE5) -> 0
A6: SOBRETAPA VV VERDE SF QUALA | B6: 0 | C6: 0 | D6: 0 | E6: 0 | F6: 0 | G6: 0 | H6: 0 | I6: 0 | J6: 0 | K6: 0 | L6: 0 | M6: 0 | N6: 0 | O6: 0 | P6: 0 | Q6: 0 | R6: 0 | S6: 0 | T6: 0 | U6: 0 | V6: 0 | W6: 0 | X6: 0 | Y6: 0 | Z6: 0 | AA6: 0 | AB6: 0 | AC6: 0 | AD6: 0 | AE6: 0 | AF6: =AVERAGE(B6:AE6) -> 0
A7: MAQUILA ENV 400 CRISTAL 17 GR S.M. PET CAPRI | B7: 24 | C7: 14 | D7: 23 | E7: 15 | F7: 57 | G7: 38 | H7: 19 | I7: 31 | J7: 23 | K7: 16 | L7: 17 | M7: 42 | N7: 19 | O7: 45 | P7: 12 | Q7: 134 | R7: 100 | S7: 13 | T7: 40 | U7: 16 | V7: 25 | W7: 35 | X7: 28 | Y7: 21 | Z7: 20 | AA7: 59 | AB7: 31 | AC7: 25 | AD7: 43 | AE7: 27 | AF7: =AVERAGE(B7:AE7) -> 33.733333
A8: MAQUILA ENV 1000 PET CAPRI NUEVO 31 GR TRANSP SM | B8: 0 | C8: 0 | D8: 0 | E8: 0 | F8: 0 | G8: 0 | H8: 0 | I8: 0 | J8: 0 | K8: 0 | L8: 0 | M8: 0 | N8: 0 | O8: 0 | P8: 0 | Q8: 0 | R8: 0 | S8: 0 | T8: 0 | U8: 0 | V8: 0 | W8: 0 | X8: 0 | Y8: 0 | Z8: 0 | AA8: 0 | AB8: 0 | AC8: 0 | AD8: 0 | AE8: 0 | AF8: =AVERAGE(B8:AE8) -> 0
A9: MAQULA ENVE 335 CM3 PET PETALOIDE TRANS 18 GR | B9: 0 | C9: 0 | D9: 0 | E9: 0 | F9: 0 | G9: 0 | H9: 0 | I9: 0 | J9: 0 | K9: 0 | L9: 0 | M9: 0 | N9: 0 | O9: 0 | P9: 0 | Q9: 0 | R9: 0 | S9: 0 | T9: 0 | U9: 0 | V9: 0 | W9: 0 | X9: 0 | Y9: 0 | Z9: 0 | AA9: 0 | AB9: 0 | AC9: 0 | AD9: 0 | AE9: 0 | AF9: =AVERAGE(B9:AE9) -> 0
A10: TAPA 28 MM CONICA AMARILLA | B10: 0 | C10: 0 | D10: 0 | E10: 0 | F10: 0 | G10: 0 | H10: 0 | I10: 0 | J10: 0 | K10: 0 | L10: 0 | M10: 0 | N10: 0 | O10: 0 | P10: 0 | Q10: 0 | R10: 0 | S10: 0 | T10: 0 | U10: 0 | V10: 0 | W10: 0 | X10: 0 | Y10: 0 | Z10: 0 | AA10: 0 | AB10: 0 | AC10: 0 | AD10: 0 | AE10: 0 | AF10: =AVERAGE(B10:AE10) -> 0
A11: MAQUILA BOTELLA W240 QUALA | B11: 0 | C11: 0 | D11: 0 | E11: 0 | F11: 0 | G11: 0 | H11: 0 | I11: 0 | J11: 0 | K11: 0 | L11: 0 | M11: 0 | N11: 0 | O11: 0 | P11: 0 | Q11: 0 | R11: 0 | S11: 0 | T11: 0 | U11: 0 | V11: 0 | W11: 0 | X11: 0 | Y11: 0 | Z11: 0 | AA11: 0 | AB11: 0 | AC11: 0 | AD11: 0 | AE11: 0 | AF11: =AVERAGE(B11:AE11) -> 0
A12: PREFORMA SN 20 GRS CRISTAL | B12: 0 | C12: 0 | D12: 0 | E12: 0 | F12: 0 | G12: 0 | H12: 0 | I12: 0 | J12: 0 | K12: 0 | L12: 0 | M12: 0 | N12: 0 | O12: 0 | P12: 0 | Q12: 0 | R12: 0 | S12: 0 | T12: 0 | U12: 0 | V12: 0 | W12: 0 | X12: 0 | Y12: 0 | Z12: 0 | AA12: 0 | AB12: 0 | AC12: 0 | AD12: 0 | AE12: 0 | AF12: =AVERAGE(B12:AE12) -> 0
A13: TAPA PP ARO DEEP BLUE 90 ML | B13: 0 | C13: 0 | D13: 0 | E13: 0 | F13: 0 | G13: 0 | H13: 0 | I13: 0 | J13: 0 | K13: 0 | L13: 0 | M13: 0 | N13: 0 | O13: 0 | P13: 0 | Q13: 0 | R13: 0 | S13: 0 | T13: 0 | U13: 0 | V13: 0 | W13: 0 | X13: 0 | Y13: 0 | Z13: 0 | AA13: 0 | AB13: 0 | AC13: 0 | AD13: 0 | AE13: 0 | AF13: =AVERAGE(B13:AE13) -> 0
A14: ENVASE 600 BALA ML PET 20 GR | B14: 0 | C14: 0 | D14: 0 | E14: 0 | F14: 0 | G14: 0 | H14: 0 | I14: 0 | J14: 0 | K14: 0 | L14: 0 | M14: 0 | N14: 0 | O14: 0 | P14: 0 | Q14: 0 | R14: 0 | S14: 0 | T14: 0 | U14: 0 | V14: 0 | W14: 0 | X14: 0 | Y14: 0 | Z14: 0 | AA14: 0 | AB14: 0 | AC14: 0 | AD14: 0 | AE14: 0 | AF14: =AVERAGE(B14:AE14) -> 0
... A202: TAPA DETERGENTE AZUL PP | B202: 14 | C202: 12 | D202: 13 | E202: 30 | F202: 26 | G202: 62 | H202: 95 | I202: 56 | J202: 20 | K202: 51 | L202: 36 | M202: 32 | N202: 14 | O202: 29 | P202: 47 | Q202: 57 | R202: 50 | S202: 12 | T202: 162 | U202: 15 | V202: 59 | W202: 19 | X202: 27 | Y202: 19 | Z202: 42 | AA202: 13 | AB202: 42 | AC202: 20 | AD202: 40 | AE202: 40 | AF202: =AVERAGE(B202:AE202) -> 38.466667
B203: 0 | C203: 0 | D203: 0 | E203: 0 | F203: 0 | G203: 0 | H203: 0 | I203: 0 | J203: 0 | K203: 0 | L203: 0 | M203: 0 | N203: 0 | O203: 0 | P203: 0 | Q203: 0 | R203: 0 | S203: 0 | T203: 0 | U203: 0 | V203: 0 | W203: 0 | X203: 0 | Y203: 0 | Z203: 0 | AA203: 0 | AB203: 0 | AC203: 0 | AD203: 0 | AE203: 0

Sheet Datos M6
A1: TIEMPO REGISTRADO EN SEGUNDOS POR UNA UNIDAD DE PRODUCTO
A2: PRODUCTO | B2: Registro 1 | C2: Registro 2 | D2: Registro 3 | E2: Registro 4 | F2: Registro 5 | G2: Registro 6 | H2: Registro 7 | I2: Registro 8 | J2: Registro 9 | K2: Registro 10 | L2: Registro 11 | M2: Registro 12 | N2: Registro 13 | O2: Registro 14 | P2: Registro 15 | Q2: Registro 16 | R2: Registro 17 | S2: Registro 18 | T2: Registro 19 | U2: Registro 20 | V2: Registro 21 | W2: Registro 22 | X2: Registro 23 | Y2: Registro 24 | Z2: Registro 25 | AA2: Registro 26 | AB2: Registro 27 | AC2: Registro 28 | AD2: Registro 29 | AE2: Registro 30 | AF2: Promedio
A3: SOBRETAPA SAVILOE 33M | B3: 12 | C3: 60 | D3: 26 | E3: 62 | F3: 37 | G3: 38 | H3: 45 | I3: 37 | J3: 35 | K3: 20 | L3: 74 | M3: 18 | N3: 65 | O3: 30 | P3: 51 | Q3: 19 | R3: 22 | S3: 64 | T3: 79 | U3: 13 | V3: 32 | W3: 27 | X3: 56 | Y3: 27 | Z3: 44 | AA3: 14 | AB3: 29 | AC3: 36 | AD3: 80 | AE3: 181 | AF3: =AVERAGE(B3:AE3) -> 44.433333
A4: MAQUILA ENV 1700 TRANSP CAPRI GEN.NUEVO 41 GR SM | B4: 0 | C4: 0 | D4: 0 | E4: 0 | F4: 0 | G4: 0 | H4: 0 | I4: 0 | J4: 0 | K4: 0 | L4: 0 | M4: 0 | N4: 0 | O4: 0 | P4: 0 | Q4: 0 | R4: 0 | S4: 0 | T4: 0 | U4: 0 | V4: 0 | W4: 0 | X4: 0 | Y4: 0 | Z4: 0 | AA4: 0 | AB4: 0 | AC4: 0 | AD4: 0 | AE4: 0 | AF4: =AVERAGE(B4:AE4) -> 0
A5: MAQUILA ENV 400 CRISTAL 19 GR S.M. PET CAPRI | B5: 30 | C5: 23 | D5: 20 | E5: 44 | F5: 66 | G5: 53 | H5: 22 | I5: 29 | J5: 31 | K5: 66 | L5: 79 | M5: 20 | N5: 12 | O5: 49 | P5: 14 | Q5: 55 | R5: 19 | S5: 19 | T5: 135 | U5: 34 | V5: 17 | W5: 48 | X5: 193 | Y5: 12 | Z5: 72 | AA5: 78 | AB5: 49 | AC5: 14 | AD5: 79 | AE5: 89 | AF5: =AVERAGE(B5:AE5) -> 49.033333
A6: SOBRETAPA VV VERDE SF QUALA | B6: 78 | C6: 93 | D6: 29 | E6: 13 | F6: 34 | G6: 79 | H6: 66 | I6: 148 | J6: 15 | K6: 72 | L6: 15 | M6: 17 | N6: 93 | O6: 274 | P6: 15 | Q6: 103 | R6: 143 | S6: 28 | T6: 16 | U6: 53 | V6: 33 | W6: 52 | X6: 25 | Y6: 48 | Z6: 84 | AA6: 39 | AB6: 30 | AC6: 18 | AD6: 12 | AE6: 15 | AF6: =AVERAGE(B6:AE6) -> 58
A7: MAQUILA ENV 400 CRISTAL 17 GR S.M. PET CAPRI | B7: 27 | C7: 81 | D7: 39 | E7: 100 | F7: 39 | G7: 17 | H7: 19 | I7: 101 | J7: 16 | K7: 92 | L7: 31 | M7: 16 | N7: 78 | O7: 75 | P7: 25 | Q7: 26 | R7: 45 | S7: 57 | T7: 27 | U7: 46 | V7: 41 | W7: 33 | X7: 75 | Y7: 36 | Z7: 23 | AA7: 22 | AB7: 22 | AC7: 75 | AD7: 52 | AE7: 37 | AF7: =AVERAGE(B7:AE7) -> 45.766667
A8: MAQUILA ENV 1000 PET CAPRI NUEVO 31 GR TRANSP SM | B8: 67 | C8: 37 | D8: 33 | E8: 13 | F8: 24 | G8: 16 | H8: 13 | I8: 14 | J8: 47 | K8: 55 | L8: 26 | M8: 20 | N8: 31 | O8: 20 | P8: 37 | Q8: 13 | R8: 28 | S8: 45 | T8: 25 | U8: 65 | V8: 146 | W8: 58 | X8: 29 | Y8: 18 | Z8: 19 | AA8: 102 | AB8: 18 | AC8: 32 | AD8: 31 | AE8: 48 | AF8: =AVERAGE(B8:AE8) -> 37.666667
A9: MAQULA ENVE 335 CM3 PET PETALOIDE TRANS 18 GR | B9: 25 | C9: 19 | D9: 18 | E9: 35 | F9: 13 | G9: 87 | H9: 152 | I9: 20 | J9: 35 | K9: 110 | L9: 27 | M9: 53 | N9: 20 | O9: 16 | P9: 44 | Q9: 109 | R9: 119 | S9: 77 | T9: 73 | U9: 132 | V9: 44 | W9: 214 | X9: 24 | Y9: 35 | Z9: 33 | AA9: 27 | AB9: 17 | AC9: 23 | AD9: 17 | AE9: 14 | AF9: =AVERAGE(B9:AE9) -> 54.4
A10: TAPA 28 MM CONICA AMARILLA | B10: 14 | C10: 29 | D10: 14 | E10: 120 | F10: 80 | G10: 69 | H10: 204 | I10: 78 | J10: 130 | K10: 35 | L10: 121 | M10: 100 | N10: 29 | O10: 32 | P10: 84 | Q10: 44 | R10: 147 | S10: 17 | T10: 116 | U10: 18 | V10: 60 | W10: 42 | X10: 43 | Y10: 66 | Z10: 29 | AA10: 20 | AB10: 65 | AC10: 62 | AD10: 87 | AE10: 80 | AF10: =AVERAGE(B10:AE10) -> 67.833333
A11: MAQUILA BOTELLA W240 QUALA | B11: 29 | C11: 92 | D11: 173 | E11: 26 | F11: 98 | G11: 56 | H11: 50 | I11: 156 | J11: 52 | K11: 81 | L11: 139 | M11: 121 | N11: 17 | O11: 34 | P11: 74 | Q11: 41 | R11: 43 | S11: 20 | T11: 26 | U11: 38 | V11: 67 | W11: 85 | X11: 55 | Y11: 69 | Z11: 202 | AA11: 34 | AB11: 12 | AC11: 33 | AD11: 17 | AE11: 37 | AF11: =AVERAGE(B11:AE11) -> 65.9
A12: PREFORMA SN 20 GRS CRISTAL | B12: 18 | C12: 68 | D12: 36 | E12: 41 | F12: 32 | G12: 57 | H12: 35 | I12: 43 | J12: 62 | K12: 138 | L12: 108 | M12: 43 | N12: 209 | O12: 133 | P12: 13 | Q12: 30 | R12: 16 | S12: 48 | T12: 32 | U12: 118 | V12: 107 | W12: 97 | X12: 110 | Y12: 77 | Z12: 62 | AA12: 99 | AB12: 120 | AC12: 13 | AD12: 220 | AE12: 61 | AF12: =AVERAGE(B12:AE12) -> 74.866667
A13: TAPA PP ARO DEEP BLUE 90 ML | B13: 45 | C13: 373 | D13: 32 | E13: 38 | F13: 30 | G13: 19 | H13: 13 | I13: 27 | J13: 22 | K13: 33 | L13: 21 | M13: 70 | N13: 14 | O13: 16 | P13: 51 | Q13: 99 | R13: 79 | S13: 21 | T13: 14 | U13: 27 | V13: 51 | W13: 80 | X13: 14 | Y13: 132 | Z13: 19 | AA13: 30 | AB13: 81 | AC13: 28 | AD13: 79 | AE13: 62 | AF13: =AVERAGE(B13:AE13) -> 54
A14: ENVASE 600 BALA ML PET 20 GR | B14: 20 | C14: 297 | D14: 20 | E14: 65 | F14: 41 | G14: 16 | H14: 43 | I14: 84 | J14: 19 | K14: 119 | L14: 37 | M14: 129 | N14: 32 | O14: 29 | P14: 218 | Q14: 14 | R14: 268 | S14: 73 | T14: 172 | U14: 27 | V14: 20 | W14: 30 | X14: 66 | Y14: 153 | Z14: 232 | AA14: 137 | AB14: 66 | AC14: 30 | AD14: 128 | AE14: 47 | AF14: =AVERAGE(B14:AE14) -> 87.733333
... A202: TAPA DETERGENTE AZUL PP | B202: 37 | C202: 42 | D202: 18 | E202: 46 | F202: 13 | G202: 55 | H202: 21 | I202: 61 | J202: 21 | K202: 86 | L202: 64 | M202: 13 | N202: 31 | O202: 55 | P202: 109 | Q202: 14 | R202: 22 | S202: 20 | T202: 61 | U202: 21 | V202: 19 | W202: 30 | X202: 16 | Y202: 70 | Z202: 52 | AA202: 46 | AB202: 12 | AC202: 50 | AD202: 14 | AE202: 89 | AF202: =AVERAGE(B202:AE202) -> 40.266667
B203: 22 | C203: 47 | D203: 28 | E203: 12 | F203: 43 | G203: 12 | H203: 83 | I203: 35 | J203: 32 | K203: 19 | L203: 117 | M203: 45 | N203: 13 | O203: 114 | P203: 48 | Q203: 31 | R203: 46 | S203: 56 | T203: 57 | U203: 140 | V203: 54 | W203: 38 | X203: 61 | Y203: 28 | Z203: 29 | AA203: 76 | AB203: 58 | AC203: 79 | AD203: 52 | AE203: 16

Sheet Datos M7
A1: TIEMPO REGISTRADO EN SEGUNDOS POR UNA UNIDAD DE PRODUCTO
A2: PRODUCTO | B2: Registro 1 | C2: Registro 2 | D2: Registro 3 | E2: Registro 4 | F2: Registro 5 | G2: Registro 6 | H2: Registro 7 | I2: Registro 8 | J2: Registro 9 | K2: Registro 10 | L2: Registro 11 | M2: Registro 12 | N2: Registro 13 | O2: Registro 14 | P2: Registro 15 | Q2: Registro 16 | R2: Registro 17 | S2: Registro 18 | T2: Registro 19 | U2: Registro 20 | V2: Registro 21 | W2: Registro 22 | X2: Registro 23 | Y2: Registro 24 | Z2: Registro 25 | AA2: Registro 26 | AB2: Registro 27 | AC2: Registro 28 | AD2: Registro 29 | AE2: Registro 30 | AF2: Promedio
A3: SOBRETAPA SAVILOE 33M | B3: 84 | C3: 12 | D3: 65 | E3: 43 | F3: 19 | G3: 38 | H3: 131 | I3: 24 | J3: 28 | K3: 83 | L3: 17 | M3: 23 | N3: 26 | O3: 12 | P3: 25 | Q3: 14 | R3: 25 | S3: 19 | T3: 29 | U3: 42 | V3: 24 | W3: 33 | X3: 41 | Y3: 28 | Z3: 21 | AA3: 52 | AB3: 40 | AC3: 50 | AD3: 25 | AE3: 42 | AF3: =AVERAGE(B3:AE3) -> 37.166667
A4: MAQUILA ENV 1700 TRANSP CAPRI GEN.NUEVO 41 GR SM | B4: 54 | C4: 84 | D4: 31 | E4: 55 | F4: 83 | G4: 16 | H4: 25 | I4: 74 | J4: 39 | K4: 26 | L4: 24 | M4: 24 | N4: 23 | O4: 43 | P4: 28 | Q4: 75 | R4: 51 | S4: 16 | T4: 32 | U4: 79 | V4: 25 | W4: 55 | X4: 33 | Y4: 57 | Z4: 34 | AA4: 76 | AB4: 81 | AC4: 23 | AD4: 16 | AE4: 21 | AF4: =AVERAGE(B4:AE4) -> 43.433333
A5: MAQUILA ENV 400 CRISTAL 19 GR S.M. PET CAPRI | B5: 40 | C5: 20 | D5: 26 | E5: 101 | F5: 76 | G5: 75 | H5: 66 | I5: 13 | J5: 69 | K5: 85 | L5: 86 | M5: 68 | N5: 19 | O5: 13 | P5: 12 | Q5: 29 | R5: 52 | S5: 22 | T5: 17 | U5: 101 | V5: 32 | W5: 12 | X5: 12 | Y5: 18 | Z5: 38 | AA5: 39 | AB5: 21 | AC5: 12 | AD5: 26 | AE5: 57 | AF5: =AVERAGE(B5:AE5) -> 41.9
A6: SOBRETAPA VV VERDE SF QUALA | B6: 66 | C6: 30 | D6: 32 | E6: 42 | F6: 79 | G6: 91 | H6: 135 | I6: 86 | J6: 94 | K6: 32 | L6: 29 | M6: 24 | N6: 59 | O6: 75 | P6: 374 | Q6: 70 | R6: 110 | S6: 147 | T6: 151 | U6: 45 | V6: 111 | W6: 26 | X6: 64 | Y6: 37 | Z6: 12 | AA6: 518 | AB6: 53 | AC6: 84 | AD6: 294 | AE6: 33 | AF6: =AVERAGE(B6:AE6) -> 100.1
A7: MAQUILA ENV 400 CRISTAL 17 GR S.M. PET CAPRI | B7: 16 | C7: 179 | D7: 66 | E7: 22 | F7: 81 | G7: 93 | H7: 167 | I7: 27 | J7: 101 | K7: 93 | L7: 75 | M7: 17 | N7: 37 | O7: 182 | P7: 102 | Q7: 48 | R7: 53 | S7: 82 | T7: 260 | U7: 14 | V7: 169 | W7: 140 | X7: 89 | Y7: 48 | Z7: 81 | AA7: 45 | AB7: 34 | AC7: 52 | AD7: 91 | AE7: 25 | AF7: =AVERAGE(B7:AE7) -> 82.966667
A8: MAQUILA ENV 1000 PET CAPRI NUEVO 31 GR TRANSP SM | B8: 94 | C8: 17 | D8: 21 | E8: 21 | F8: 41 | G8: 18 | H8: 30 | I8: 13 | J8: 57 | K8: 39 | L8: 14 | M8: 64 | N8: 13 | O8: 16 | P8: 29 | Q8: 32 | R8: 100 | S8: 13 | T8: 67 | U8: 47 | V8: 61 | W8: 26 | X8: 75 | Y8: 63 | Z8: 73 | AA8: 24 | AB8: 25 | AC8: 20 | AD8: 189 | AE8: 36 | AF8: =AVERAGE(B8:AE8) -> 44.6
A9: MAQULA ENVE 335 CM3 PET PETALOIDE TRANS 18 GR | B9: 71 | C9: 25 | D9: 53 | E9: 30 | F9: 106 | G9: 250 | H9: 53 | I9: 172 | J9: 72 | K9: 35 | L9: 43 | M9: 25 | N9: 45 | O9: 17 | P9: 18 | Q9: 39 | R9: 38 | S9: 23 | T9: 35 | U9: 99 | V9: 13 | W9: 47 | X9: 129 | Y9: 79 | Z9: 25 | AA9: 25 | AB9: 34 | AC9: 39 | AD9: 20 | AE9: 16 | AF9: =AVERAGE(B9:AE9) -> 55.866667
A10: TAPA 28 MM CONICA AMARILLA | B10: 13 | C10: 116 | D10: 36 | E10: 34 | F10: 45 | G10: 140 | H10: 16 | I10: 60 | J10: 64 | K10: 12 | L10: 64 | M10: 19 | N10: 15 | O10: 14 | P10: 25 | Q10: 102 | R10: 42 | S10: 19 | T10: 55 | U10: 24 | V10: 114 | W10: 17 | X10: 29 | Y10: 12 | Z10: 39 | AA10: 18 | AB10: 71 | AC10: 18 | AD10: 106 | AE10: 96 | AF10: =AVERAGE(B10:AE10) -> 47.833333
A11: MAQUILA BOTELLA W240 QUALA | B11: 33 | C11: 16 | D11: 44 | E11: 14 | F11: 43 | G11: 20 | H11: 84 | I11: 44 | J11: 21 | K11: 16 | L11: 25 | M11: 76 | N11: 50 | O11: 32 | P11: 15 | Q11: 37 | R11: 110 | S11: 61 | T11: 22 | U11: 18 | V11: 28 | W11: 14 | X11: 24 | Y11: 57 | Z11: 16 | AA11: 28 | AB11: 13 | AC11: 54 | AD11: 46 | AE11: 55 | AF11: =AVERAGE(B11:AE11) -> 37.2
A12: PREFORMA SN 20 GRS CRISTAL | B12: 57 | C12: 46 | D12: 157 | E12: 97 | F12: 45 | G12: 23 | H12: 119 | I12: 159 | J12: 21 | K12: 279 | L12: 16 | M12: 52 | N12: 17 | O12: 83 | P12: 20 | Q12: 145 | R12: 61 | S12: 162 | T12: 59 | U12: 21 | V12: 41 | W12: 21 | X12: 47 | Y12: 159 | Z12: 108 | AA12: 47 | AB12: 17 | AC12: 20 | AD12: 117 | AE12: 90 | AF12: =AVERAGE(B12:AE12) -> 76.866667
A13: TAPA PP ARO DEEP BLUE 90 ML | B13: 16 | C13: 29 | D13: 15 | E13: 24 | F13: 15 | G13: 20 | H13: 20 | I13: 26 | J13: 34 | K13: 23 | L13: 15 | M13: 47 | N13: 39 | O13: 28 | P13: 50 | Q13: 13 | R13: 59 | S13: 15 | T13: 18 | U13: 53 | V13: 24 | W13: 32 | X13: 35 | Y13: 24 | Z13: 95 | AA13: 24 | AB13: 33 | AC13: 76 | AD13: 51 | AE13: 41 | AF13: =AVERAGE(B13:AE13) -> 33.133333
A14: ENVASE 600 BALA ML PET 20 GR | B14: 43 | C14: 19 | D14: 98 | E14: 53 | F14: 58 | G14: 15 | H14: 52 | I14: 183 | J14: 40 | K14: 57 | L14: 57 | M14: 13 | N14: 56 | O14: 21 | P14: 36 | Q14: 76 | R14: 12 | S14: 41 | T14: 81 | U14: 128 | V14: 59 | W14: 182 | X14: 138 | Y14: 40 | Z14: 32 | AA14: 67 | AB14: 42 | AC14: 17 | AD14: 118 | AE14: 12 | AF14: =AVERAGE(B14:AE14) -> 61.533333
... A202: TAPA DETERGENTE AZUL PP | B202: 0 | C202: 0 | D202: 0 | E202: 0 | F202: 0 | G202: 0 | H202: 0 | I202: 0 | J202: 0 | K202: 0 | L202: 0 | M202: 0 | N202: 0 | O202: 0 | P202: 0 | Q202: 0 | R202: 0 | S202: 0 | T202: 0 | U202: 0 | V202: 0 | W202: 0 | X202: 0 | Y202: 0 | Z202: 0 | AA202: 0 | AB202: 0 | AC202: 0 | AD202: 0 | AE202: 0 | AF202: =AVERAGE(B202:AE202) -> 0
B203: 0 | C203: 0 | D203: 0 | E203: 0 | F203: 0 | G203: 0 | H203: 0 | I203: 0 | J203: 0 | K203: 0 | L203: 0 | M203: 0 | N203: 0 | O203: 0 | P203: 0 | Q203: 0 | R203: 0 | S203: 0 | T203: 0 | U203: 0 | V203: 0 | W203: 0 | X203: 0 | Y203: 0 | Z203: 0 | AA203: 0 | AB203: 0 | AC203: 0 | AD203: 0 | AE203: 0

Sheet Datos M8
A1: TIEMPO REGISTRADO EN SEGUNDOS POR UNA UNIDAD DE PRODUCTO
A2: PRODUCTO | B2: Registro 1 | C2: Registro 2 | D2: Registro 3 | E2: Registro 4 | F2: Registro 5 | G2: Registro 6 | H2: Registro 7 | I2: Registro 8 | J2: Registro 9 | K2: Registro 10 | L2: Registro 11 | M2: Registro 12 | N2: Registro 13 | O2: Registro 14 | P2: Registro 15 | Q2: Registro 16 | R2: Registro 17 | S2: Registro 18 | T2: Registro 19 | U2: Registro 20 | V2: Registro 21 | W2: Registro 22 | X2: Registro 23 | Y2: Registro 24 | Z2: Registro 25 | AA2: Registro 26 | AB2: Registro 27 | AC2: Registro 28 | AD2: Registro 29 | AE2: Registro 30 | AF2: Promedio
A3: SOBRETAPA SAVILOE 33M | B3: 0 | C3: 0 | D3: 0 | E3: 0 | F3: 0 | G3: 0 | H3: 0 | I3: 0 | J3: 0 | K3: 0 | L3: 0 | M3: 0 | N3: 0 | O3: 0 | P3: 0 | Q3: 0 | R3: 0 | S3: 0 | T3: 0 | U3: 0 | V3: 0 | W3: 0 | X3: 0 | Y3: 0 | Z3: 0 | AA3: 0 | AB3: 0 | AC3: 0 | AD3: 0 | AE3: 0 | AF3: =AVERAGE(B3:AE3) -> 0
